Workbook
Name _1234\5678\90: CORE!$G$21
Name _1234\5678\91: CORE!$F$21
Name a: CORE!$B$2:$C$3
Name b: CORE!$D$2:$E$3
Name d: CORE!$B$4:$C$5
Name e: CORE!$D$4:$E$5
Name f: CORE!$G$2:$H$5
Name g: REF!$B$2:$B$5
Name h: CORE!$K$4:$K$6 CORE!$J$5:$L$5
Name i: SUM(CORE!$M$4:$N$5,h)
Name l: h+i
Name m: [1]Sheet1!$A$1
Name MYLAMBDA: _xlfn.LAMBDA(_xlpm.x,_xlpm.y,_xlpm.z,SUM(_xlpm.x*2,_xlpm.y*3,-_xlpm.z,LOGICAL!$D$12))
Name NAMEDCELL123: "'ciao"
Name QF_SYS_LISTPRICECURRENCY: CORE!$F$12

Sheet COVERAGE
A1: AREA | B1: FUNCTIONS
B2: IMPLEMENTED | C2: MISSING | D2: TOTAL | E2: COVERAGE | F2: MISSING RESPECT TOT
A3: AUTOMATION | B3: =COUNTIF(AUTOMATION!B$3:B$245,"=DONE") -> 0 | C3: =D3-B3 -> 3 | D3: =COUNTA(AUTOMATION!A$3:A$245) -> 3 | E3: =B3/D3 -> 0 | F3: =C3/D$18 -> 0.0055970149
A4: COMPATIBILITY | B4: =COUNTIF(COMPATIBILITY!B$3:B$97,"=DONE") -> 40 | C4: =D4-B4 -> 0 | D4: =COUNTA(COMPATIBILITY!A$3:A$97) -> 40 | E4: =B4/D4 -> 1 | F4: =C4/D$18 -> 0
A5: CUBE | B5: =COUNTIF(CUBE!B$3:B$92,"=DONE") -> 0 | C5: =D5-B5 -> 7 | D5: =COUNTA(CUBE!A$3:A$92) -> 7 | E5: =B5/D5 -> 0 | F5: =C5/D$18 -> 0.013059701
A6: DATABASE | B6: =COUNTIF(DATABASE!B$3:B$92,"=DONE") -> 0 | C6: =D6-B6 -> 12 | D6: =COUNTA(DATABASE!A$3:A$92) -> 12 | E6: =B6/D6 -> 0 | F6: =C6/D$18 -> 0.02238806
A7: DATE & TIME | B7: =COUNTIF('DATE & TIME'!B$3:B$245,"=DONE") -> 25 | C7: =D7-B7 -> 0 | D7: =COUNTA('DATE & TIME'!A$3:A$245) -> 25 | E7: =B7/D7 -> 1 | F7: =C7/D$18 -> 0
A8: ENGINEERING | B8: =COUNTIF(ENGINEERING!B$3:B$66,"=DONE") -> 54 | C8: =D8-B8 -> 0 | D8: =COUNTA(ENGINEERING!A$3:A$66) -> 54 | E8: =B8/D8 -> 1 | F8: =C8/D$18 -> 0
A9: FINANCIAL | B9: =COUNTIF(FINANCIAL!B$3:B$246,"=DONE") -> 55 | C9: =D9-B9 -> 0 | D9: =COUNTA(FINANCIAL!A$3:A$246) -> 55 | E9: =B9/D9 -> 1 | F9: =C9/D$18 -> 0
A10: INFORMATION | B10: =COUNTIF(INFORMATION!B$3:B$278,"=DONE") -> 16 | C10: =D10-B10 -> 6 | D10: =COUNTA(INFORMATION!A$3:A$278) -> 22 | E10: =B10/D10 -> 0.72727273 | F10: =C10/D$18 -> 0.01119403
A11: LOGICAL | B11: =COUNTIF(LOGICAL!B$3:B$282,"=DONE") -> 19 | C11: =D11-B11 -> 0 | D11: =COUNTA(LOGICAL!A$3:A$282) -> 19 | E11: =B11/D11 -> 1 | F11: =C11/D$18 -> 0
A12: LOOKUP | B12: =COUNTIF(LOOKUP!B$3:B$353,"=DONE") -> 33 | C12: =D12-B12 -> 7 | D12: =COUNTA(LOOKUP!A$3:A$353) -> 40 | E12: =B12/D12 -> 0.825 | F12: =C12/D$18 -> 0.013059701
A13: MATH & TRIG | B13: =COUNTIF('MATH & TRIG'!B$3:B$219,"=DONE") -> 71 | C13: =D13-B13 -> 9 | D13: =COUNTA('MATH & TRIG'!A$3:A$219) -> 80 | E13: =B13/D13 -> 0.8875 | F13: =C13/D$18 -> 0.016791045
A14: STATISTICAL | B14: =COUNTIF(STATISTICAL!B$3:B$197,"=DONE") -> 111 | C14: =D14-B14 -> 0 | D14: =COUNTA(STATISTICAL!A$3:A$197) -> 111 | E14: =B14/D14 -> 1 | F14: =C14/D$18 -> 0
A15: TEXT | B15: =COUNTIF(TEXT!B$3:B$265,"=DONE") -> 44 | C15: =D15-B15 -> 6 | D15: =COUNTA(TEXT!A$3:A$265) -> 50 | E15: =B15/D15 -> 0.88 | F15: =C15/D$18 -> 0.01119403
A16: WEB | B16: =COUNTIF(WEB!B$3:B$263,"=DONE") -> 0 | C16: =D16-B16 -> 3 | D16: =COUNTA(WEB!A$3:A$263) -> 3 | E16: =B16/D16 -> 0 | F16: =C16/D$18 -> 0.0055970149
A17: OPERATORS | B17: =COUNTIF(OPERATORS!B$3:B$300,"=DONE") -> 15 | C17: =D17-B17 -> 0 | D17: =COUNTA(OPERATORS!A$3:A$300) -> 15 | E17: =B17/D17 -> 1 | F17: =C17/D$18 -> 0
A18: TOTAL | B18: =SUM(B3:B17) -> 483 | C18: =SUM(C3:C17) -> 53 | D18: =SUM(D3:D17) -> 536 | E18: =B18/D18 -> 0.9011194 | F18: =C18/D$18 -> 0.098880597

Sheet AUTOMATION
A1: COVERAGE | B1: =COUNTIF(B3:B52,"=DONE")/COUNTA(A3:A52) -> 0 | C1: INPUTS | R1: EVAL
A2: FUNCTION | B2: STATUS | C2: NUMERIC | H2: EMPTY | I2: STRING | J2: BOOL | K2: ERROR | R2: NUMERIC | W2: EMPTY | X2: STRING | Y2: BOOL | Z2: ERROR | AG2: ARRAY -> VALUE | AH2: ARRAY -> ARRAY
A3: CALL
A4: EUROCONVERT
A5: REGISTER.ID

Sheet COMPATIBILITY
A1: COVERAGE | B1: =COUNTIF(B3:B97,"=DONE")/COUNTA(A3:A97) -> 1 | C1: INPUTS | R1: EVAL
A2: FUNCTION | B2: STATUS | C2: NUMERIC | H2: EMPTY | I2: STRING | J2: BOOL | K2: ERROR | R2: NUMERIC | W2: EMPTY | X2: STRING | Y2: BOOL | Z2: ERROR | AG2: ARRAY -> VALUE | AH2: ARRAY -> ARRAY
A3: BETADIST | B3: DONE | C3: 0 | D3: 5 | E3: 0.7 | F3: 3 | G3: 4 | I3: 29/02/1900 | J3: TRUE | K3: #VALUE! | L3: #N/A | M3: #DIV/0! | N3: #NAME? | O3: #NULL! | P3: #NUM! | Q3: #REF! | R3: =BETADIST(C3,,,) -> #NUM! | S3: =BETADIST(D3,1,2) -> #NUM! | T3: =BETADIST(E3,"1","3", 0.5, 5) -> 0.1274952 | U3: =BETADIST(F3,-1,2) -> #NUM! | V3: =BETADIST(G3, 0,0) -> #NUM! | W3: =BETADIST(H3,H3,G3) -> #NUM! | X3: =BETADIST(I3,,I3) -> #NUM! | Y3: =BETADIST(J3,I3,E3) -> 1 | Z3: =BETADIST(K3,I3,G3) -> #VALUE! | AA3: =BETADIST(L3,J3,H3) -> #N/A | AB3: =BETADIST(M3,K3,I3) -> #DIV/0! | AC3: =BETADIST(N3,L3,J3) -> #NAME? | AD3: =BETADIST(O3,M3,K3) -> #NULL! | AE3: =BETADIST(P3,N3,L3) -> #NUM! | AF3: =BETADIST(Q3,O3,M3) -> #REF! | AG3: {=BETADIST(C3:Q3,3,3)} -> 0 | AH3: {=BETADIST(C3:Q3,3,4)} -> 0 | AI3: #NUM! | AJ3: 0.92953 | AK3: #NUM! | AL3: #NUM! | AM3: 0 | AN3: #NUM! | AO3: 1 | AP3: #VALUE! | AQ3: #N/A | AR3: #DIV/0! | AS3: #NAME? | AT3: #NULL! | AU3: #NUM! | AV3: #REF! | AW3: #N/A
A4: BETAINV | B4: DONE | C4: 0 | D4: 0.1 | E4: 0.7 | F4: 0.002 | G4: 4 | I4: 13/01/1900 | J4: TRUE | K4: #VALUE! | L4: #N/A | M4: #DIV/0! | N4: #NAME? | O4: #NULL! | P4: #NUM! | Q4: #REF! | R4: =BETAINV(C4,4,4) -> #NUM! | S4: =BETAINV(D4,2,2) -> 0.19580011 | T4: =BETAINV(0.4,2,E4) -> 0.73329229 | U4: =BETAINV(F4,4,3) -> 0.11264101 | V4: =BETAINV(G4,D4,E4) -> #NUM! | W4: =BETAINV(H4,3,2) -> #NUM! | X4: =BETAINV(0.9,I4, 1) -> 0.9919281 | Y4: =BETAINV(0.3,J4,2) -> 0.16333997 | Z4: =BETAINV(K4,C4,E4) -> #VALUE! | AA4: =BETAINV(L4,D4,F4) -> #N/A | AB4: =BETAINV(M4,E4,G4) -> #DIV/0! | AC4: =BETAINV(N4,F4,H4) -> #NAME? | AD4: =BETAINV(O4,G4,I4) -> #NULL! | AE4: =BETAINV(P4,H4,J4) -> #NUM! | AF4: =BETAINV(Q4,I4,K4) -> #REF! | AG4: {=BETAINV(C4:Q4,3,3)} -> #NUM! | AH4: {=BETAINV(C4:Q4, 3,2)} -> #NUM! | AI4: 0.32046058 | AJ4: 0.72761606 | AK4: 0.081046636 | AL4: #NUM! | AM4: #NUM! | AN4: #NUM! | AO4: #NUM! | AP4: #VALUE! | AQ4: #N/A | AR4: #DIV/0! | AS4: #NAME? | AT4: #NULL! | AU4: #NUM! | AV4: #REF! | AW4: #N/A
A5: BINOMDIST | B5: DONE | C5: 0 | D5: 5 | E5: 0.7 | F5: 3 | G5: 4 | I5: 29/02/1900 | J5: TRUE | K5: #VALUE! | L5: #N/A | M5: #DIV/0! | N5: #NAME? | O5: #NULL! | P5: #NUM! | Q5: #REF! | R5: =BINOMDIST(C5,,,) -> 1 | S5: =BINOMDIST(D5,10,0.2,FALSE) -> 0.026424115 | T5: =BINOMDIST(E5,"1",".3",5) -> 0.7 | U5: =BINOMDIST(F5,-1,0.2,"TRUE") -> #NUM! | V5: =BINOMDIST(G5, 7,0.4,1) -> 0.903744 | W5: =BINOMDIST(H5,H5,G5/7,1) -> 1 | X5: =BINOMDIST(I5,I5,,1) -> 1 | Y5: =BINOMDIST(J5,I5,E5,1) -> 5.9771533e-30 | Z5: =BINOMDIST(K5,I5,G5,1) -> #VALUE! | AA5: =BINOMDIST(L5,J5,H5,1) -> #N/A | AB5: =BINOMDIST(M5,K5,I5,1) -> #DIV/0! | AC5: =BINOMDIST(N5,L5,J5,1) -> #NAME? | AD5: =BINOMDIST(O5,M5,K5,1) -> #NULL! | AE5: =BINOMDIST(P5,N5,L5,1) -> #NUM! | AF5: =BINOMDIST(Q5,O5,M5,1) -> #REF! | AG5: {=BINOMDIST(C5:Q5,3,0.3,1)} -> 0.343 | AH5: {=BINOMDIST(C5:Q5,3,0.4,1)} -> 0.216 | AI5: #NUM! | AJ5: 0.216 | AK5: 1 | AL5: #NUM! | AM5: 0.216 | AN5: #NUM! | AO5: 0.648 | AP5: #VALUE! | AQ5: #N/A | AR5: #DIV/0! | AS5: #NAME? | AT5: #NULL! | AU5: #NUM! | AV5: #REF! | AW5: #N/A
A6: CEILING | B6: DONE | C6: 2.5 | D6: -255.5 | E6: -2.5 | F6: 5 | G6: 0.234 | I6: ciao | J6: TRUE | K6: #VALUE! | L6: #N/A | M6: #DIV/0! | N6: #NAME? | O6: #NULL! | P6: #NUM! | Q6: #REF! | R6: =CEILING(C6,1) -> 3 | S6: =CEILING(D6,-2) -> -256 | T6: =CEILING(E6,2) -> -2 | U6: =CEILING(F6,0) -> 0 | V6: =CEILING(G6,0.01) -> 0.24 | W6: =CEILING(H6,-2) -> 0 | X6: =CEILING(I6,0) -> #VALUE! | Y6: =CEILING(J6,0) -> 0 | Z6: =CEILING(2.3,K6) -> #VALUE! | AA6: =CEILING(2.3,L6) -> #N/A | AB6: =CEILING(2.3,M6) -> #DIV/0! | AC6: =CEILING(2.3,N6) -> #NAME? | AD6: =CEILING(2.3,O6) -> #NULL! | AE6: =CEILING(2.3,P6) -> #NUM! | AF6: =CEILING(2.3,Q6) -> #REF! | AH6: {=CEILING(C6:P6,D6:Q6)} -> #NUM! | AI6: -257.5 | AJ6: 0 | AK6: 5.148 | AL6: 0 | AM6: #VALUE! | AN6: #VALUE! | AO6: #VALUE! | AP6: #VALUE! | AQ6: #N/A | AR6: #DIV/0! | AS6: #NAME? | AT6: #NULL! | AU6: #NUM! | AV6: #N/A | AW6: #N/A
A7: CHIDIST | B7: DONE | C7: 0 | D7: 5 | E7: 0.7 | F7: 3 | G7: 4 | I7: 29/02/1900 | J7: TRUE | K7: #VALUE! | L7: #N/A | M7: #DIV/0! | N7: #NAME? | O7: #NULL! | P7: #NUM! | Q7: #REF! | R7: =CHIDIST(C7,) -> #NUM! | S7: =CHIDIST(D7,10) -> 0.89117802 | T7: =CHIDIST(E7,"1") -> 0.40278369 | U7: =CHIDIST(F7,-1) -> #NUM! | V7: =CHIDIST(G7, 7) -> 0.77977741 | W7: =CHIDIST(H7,H7) -> #NUM! | X7: =CHIDIST(I7,I7) -> 0.47571699 | Y7: =CHIDIST(J7,J7) -> 0.31731051 | Z7: =CHIDIST(K7,K7) -> #VALUE! | AA7: =CHIDIST(L7,L7) -> #N/A | AB7: =CHIDIST(M7,M7) -> #DIV/0! | AC7: =CHIDIST(N7,N7) -> #NAME? | AD7: =CHIDIST(O7,O7) -> #NULL! | ... AF7: =CHIDIST(Q7,Q7) -> #REF! | AG7: {=CHIDIST(C7:Q7,3)} -> 1 | AH7: {=CHIDIST(C7:Q7,3)} -> 1 | AI7: 0.17179714 | AJ7: 0.87320395 | AK7: 0.39162518 | AL7: 0.26146413 | AM7: 1 | AN7: 5.8782307e-13 | AO7: 0.80125196 | AP7: #VALUE! | AQ7: #N/A | AR7: #DIV/0! | AS7: #NAME? | AT7: #NULL! | AU7: #NUM! | AV7: #REF! | AW7: #N/A
A8: CHIINV | B8: DONE | C8: 10 | D8: 0.1 | E8: 0.7 | F8: 100 | G8: 4 | I8: 13/01/1900 | J8: TRUE | K8: #VALUE! | L8: #N/A | M8: #DIV/0! | N8: #NAME? | O8: #NULL! | P8: #NUM! | Q8: #REF! | R8: =CHIINV(C8,0.4) -> #NUM! | S8: =CHIINV(D8,9) -> 14.683657 | T8: =CHIINV(0.4,E8) -> #NUM! | U8: =CHIINV(0.01, F8) -> 135.80672 | V8: =CHIINV(D8,G8) -> 7.7794403 | W8: =CHIINV(H8,3) -> #NUM! | X8: =CHIINV(0.9,I8) -> 7.0415046 | Y8: =CHIINV(0.3,J8) -> 1.0741942 | Z8: =CHIINV(K8,C8) -> #VALUE! | AA8: =CHIINV(L8,D8) -> #N/A | AB8: =CHIINV(M8,E8) -> #DIV/0! | AC8: =CHIINV(N8,F8) -> #NAME? | AD8: =CHIINV(O8,G8) -> #NULL! | AE8: =CHIINV(P8,H8) -> #NUM! | AF8: =CHIINV(Q8,I8) -> #REF! | AG8: {=CHIINV(0.6, C8:Q8)} -> 8.2954718 | AH8: {=CHIINV(0.5, C8:Q8)} -> 9.3418178 | AI8: #NUM! | AJ8: #NUM! | AK8: 99.334129 | AL8: 3.356694 | AM8: #NUM! | AN8: 12.339756 | AO8: 0.45493642 | AP8: #VALUE! | AQ8: #N/A | AR8: #DIV/0! | AS8: #NAME? | AT8: #NULL! | AU8: #NUM! | AV8: #REF! | AW8: #N/A
A9: CHITEST | B9: DONE | C9: 10 | D9: 3.2 | E9: 0.7 | F9: 2 | G9: 4 | I9: 13/01/1900 | J9: TRUE | K9: #VALUE! | L9: #N/A | M9: #DIV/0! | N9: #NAME? | O9: #NULL! | P9: #NUM! | Q9: #REF! | R9: =CHITEST(C8:D9,E6:E9) -> 4.6026648e-17 | S9: =CHITEST(D9:E9,E9:G9) -> #N/A | T9: =CHITEST(E9:F9,G9:H9) -> 0.098942936 | U9: =CHITEST(D9,F9) -> #N/A | V9: =CHITEST(G9:I9,H9:J9) -> #DIV/0! | W9: =CHITEST(H9:I9,J9:K9) -> #VALUE! | X9: =CHITEST(I9:J9,K9:L9) -> #VALUE! | Y9: =CHITEST(J9:K9,L9:M9) -> #VALUE! | Z9: =CHITEST(K9:L9,M9:N9) -> #VALUE! | AA9: =CHITEST(L9:M9,N9:O9) -> #N/A | AB9: =CHITEST(M9:N9,O9:P9) -> #DIV/0! | AC9: =CHITEST(N9:O9,P9:Q9) -> #NAME? | AD9: =CHITEST(O9:P9,Q9:R9) -> #NUM! | ... AF9: =CHITEST(Q9:R9,S9:T9) -> #REF! | AG9: {=CHITEST(C8:D9, F8:G9)} -> 2.9254701e-27 | AH9: {=CHITEST(D9:E9, E9:F9)} -> 0.0017703822 | AI9: 0.0017703822 | AJ9: 0.0017703822 | AK9: 0.0017703822 | AL9: 0.0017703822 | AM9: 0.0017703822 | AN9: 0.0017703822 | AO9: 0.0017703822 | AP9: 0.0017703822 | AQ9: 0.0017703822 | AR9: 0.0017703822 | AS9: 0.0017703822 | AT9: 0.0017703822 | AU9: 0.0017703822 | AV9: 0.0017703822 | AW9: 0.0017703822
A10: CONFIDENCE | B10: DONE | C10: 0.1 | D10: 0.32 | E10: 0.7 | F10: 0.4 | G10: 0.9 | I10: 13/01/1900 | J10: TRUE | K10: #VALUE! | L10: #N/A | M10: #DIV/0! | N10: #NAME? | O10: #NULL! | P10: #NUM! | Q10: #REF! | R10: =CONFIDENCE(C10,,) -> #NUM! | S10: =CONFIDENCE(D10,10,FALSE) -> #NUM! | T10: =CONFIDENCE(E10,"1",5) -> 0.17232055 | U10: =CONFIDENCE(F10,-1,"TRUE") -> #VALUE! | V10: =CONFIDENCE(G10, 7,1) -> 0.87962943 | W10: =CONFIDENCE(H10,H10,1) -> #NUM! | X10: =CONFIDENCE(I10,I10,1) -> #NUM! | Y10: =CONFIDENCE(J10,J10,1) -> #NUM! | Z10: =CONFIDENCE(K10,K10,1) -> #VALUE! | AA10: =CONFIDENCE(L10,L10,1) -> #N/A | AB10: =CONFIDENCE(M10,M10,1) -> #DIV/0! | AC10: =CONFIDENCE(N10,N10,1) -> #NAME? | AD10: =CONFIDENCE(O10,O10,1) -> #NULL! | ... AF10: =CONFIDENCE(Q10,Q10,1) -> #REF! | AG10: {=CONFIDENCE(C10:Q10,3,1)} -> 4.9345609 | AH10: {=CONFIDENCE(C10:Q10,3,1)} -> 4.9345609 | AI10: 2.9833736 | AJ10: 1.1559614 | AK10: 2.5248637 | AL10: 0.37698404 | AM10: #NUM! | AN10: #NUM! | AO10: #NUM! | AP10: #VALUE! | AQ10: #N/A | AR10: #DIV/0! | AS10: #NAME? | AT10: #NULL! | AU10: #NUM! | AV10: #REF! | AW10: #N/A
A11: COVAR | B11: DONE | C11: 0 | D11: 0.1 | E11: 0.2 | F11: 0.3 | G11: -0.1 | I11: 29/02/1900 | J11: TRUE | K11: #VALUE! | L11: #N/A | M11: #DIV/0! | N11: #NAME? | O11: #NULL! | P11: #NUM! | Q11: #REF! | R11: =COVAR(C11:E11,E11:G11) -> -0.01 | S11: =COVAR(D11:F11,F11:H11) -> -0.01 | T11: =COVAR(E11:G11,G11:I11) -> 0 | U11: =COVAR(F11:H11,H11:J11) -> #DIV/0! | V11: =COVAR(G11:I11,I11:K11) -> #VALUE! | W11: =COVAR(H11:J11,J11:L11) -> #VALUE! | X11: =COVAR(I11:K11,K11:M11) -> #VALUE! | Y11: =COVAR(J11:L11,L11:N11) -> #N/A | ... AF11: =COVAR(Q11:S11,S11:U11) -> #REF! | AG11: {=COVAR(C11:E11,E11:G11)} -> -0.01 | AH11: {=COVAR(C11:E11,E11:G11)} -> -0.01 | AI11: -0.01 | AJ11: -0.01 | AK11: -0.01 | AL11: -0.01 | AM11: -0.01 | AN11: -0.01 | AO11: -0.01 | AP11: -0.01 | AQ11: -0.01 | AR11: -0.01 | AS11: -0.01 | AT11: -0.01 | AU11: -0.01 | AV11: -0.01 | AW11: -0.01
A12: CRITBINOM | B12: DONE | C12: 10 | D12: 0.1 | E12: 0.7 | F12: 100 | G12: 4 | I12: 13/01/1900 | J12: TRUE | K12: #VALUE! | L12: #N/A | M12: #DIV/0! | N12: #NAME? | O12: #NULL! | P12: #NUM! | Q12: #REF! | R12: =CRITBINOM(C12,0.4,0.4) -> 4 | S12: =CRITBINOM(D12,0.9,0.9) -> 0 | T12: =CRITBINOM(4,0.2,E12) -> 1 | U12: =CRITBINOM(F12,0.4,0.3) -> 37 | V12: =CRITBINOM(G12,D12,E12) -> 1 | W12: =CRITBINOM(H12,0.3,0.2) -> 0 | X12: =CRITBINOM(I12,0.9, 0.1) -> 10 | Y12: =CRITBINOM(0.3,J12,2) -> #NUM! | Z12: =CRITBINOM(K12,C12,E12) -> #VALUE! | AA12: =CRITBINOM(L12,D12,F12) -> #N/A | AB12: =CRITBINOM(M12,E12,G12) -> #DIV/0! | AC12: =CRITBINOM(N12,F12,H12) -> #NAME? | AD12: =CRITBINOM(O12,G12,I12) -> #NULL! | AE12: =CRITBINOM(P12,H12,J12) -> #NUM! | AF12: =CRITBINOM(Q12,I12,K12) -> #REF! | AG12: {=CRITBINOM(C12:Q12,0.3,0.3)} -> 2 | AH12: {=CRITBINOM(C12:Q12, 0.3,0.2)} -> 2 | AI12: 0 | AJ12: 0 | AK12: 26 | AL12: 0 | AM12: 0 | AN12: 2 | AO12: 0 | AP12: #VALUE! | AQ12: #N/A | AR12: #DIV/0! | AS12: #NAME? | AT12: #NULL! | AU12: #NUM! | AV12: #REF! | AW12: #N/A
A13: EXPONDIST | B13: DONE | C13: 0 | D13: 5 | E13: 0.7 | F13: 3 | G13: 4 | I13: 29/02/1900 | J13: TRUE | K13: #VALUE! | L13: #N/A | M13: #DIV/0! | N13: #NAME? | O13: #NULL! | P13: #NUM! | Q13: #REF! | R13: =EXPONDIST(C13,,) -> #NUM! | S13: =EXPONDIST(D13,10,FALSE) -> 1.9287498e-21 | T13: =EXPONDIST(E13,"1",5) -> 0.5034147 | U13: =EXPONDIST(F13,-1,"TRUE") -> #NUM! | V13: =EXPONDIST(G13, 7,1) -> 1 | W13: =EXPONDIST(H13,H13,1) -> #NUM! | X13: =EXPONDIST(I13,I13,1) -> 1 | Y13: =EXPONDIST(J13,I13,1) -> 1 | Z13: =EXPONDIST(K13,I13,1) -> #VALUE! | AA13: =EXPONDIST(L13,J13,1) -> #N/A | AB13: =EXPONDIST(M13,K13,1) -> #DIV/0! | AC13: =EXPONDIST(N13,L13,1) -> #NAME? | AD13: =EXPONDIST(O13,M13,1) -> #NULL! | AE13: =EXPONDIST(P13,N13,1) -> #NUM! | AF13: =EXPONDIST(Q13,O13,1) -> #REF! | AG13: {=EXPONDIST(C13:Q13,3,1)} -> 0 | AH13: {=EXPONDIST(C13:Q13,3,1)} -> 0 | AI13: 0.99999969 | AJ13: 0.87754357 | AK13: 0.99987659 | AL13: 0.99999386 | AM13: 0 | AN13: 1 | AO13: 0.95021293 | AP13: #VALUE! | AQ13: #N/A | AR13: #DIV/0! | AS13: #NAME? | AT13: #NULL! | AU13: #NUM! | AV13: #REF! | AW13: #N/A
A14: FDIST | B14: DONE | C14: 0 | D14: 5 | E14: 0.7 | F14: 3 | G14: 4 | I14: 29/02/1900 | J14: TRUE | K14: #VALUE! | L14: #N/A | M14: #DIV/0! | N14: #NAME? | O14: #NULL! | P14: #NUM! | Q14: #REF! | R14: =FDIST(C14,,) -> #NUM! | S14: =FDIST(D14,10,65) -> 2.3172483e-05 | T14: =FDIST(E14,3,"1") -> 0.68213246 | U14: =FDIST(F14,-1,32) -> #NUM! | V14: =FDIST(G14,32, 7) -> 0.031519045 | W14: =FDIST(H14,H14,32) -> #NUM! | X14: =FDIST(I14,I14,3) -> 0.0029635692 | Y14: =FDIST(J14,I14,3) -> 0.60084239 | Z14: =FDIST(K14,I14,89) -> #VALUE! | AA14: =FDIST(L14,J14,89) -> #N/A | AB14: =FDIST(M14,K14,89) -> #DIV/0! | AC14: =FDIST(N14,L14,89) -> #NAME? | AD14: =FDIST(O14,M14,89) -> #NULL! | AE14: =FDIST(P14,N14,89) -> #NUM! | AF14: =FDIST(Q14,O14,89) -> #REF! | AG14: {=FDIST(C14:Q14,3,20)} -> 1 | AH14: {=FDIST(C14:Q14,3,7)} -> 1 | AI14: 0.036673354 | AJ14: 0.58124968 | AK14: 0.10457022 | AL14: 0.059630822 | AM14: 1 | AN14: 2.3280966e-05 | AO14: 0.44707961 | AP14: #VALUE! | AQ14: #N/A | AR14: #DIV/0! | AS14: #NAME? | AT14: #NULL! | AU14: #NUM! | AV14: #REF! | AW14: #N/A
A15: FINV | B15: DONE | C15: 10 | D15: 0.1 | E15: 0.7 | F15: 100 | G15: 4 | I15: 13/01/1900 | J15: TRUE | K15: #VALUE! | L15: #N/A | M15: #DIV/0! | N15: #NAME? | O15: #NULL! | P15: #NUM! | Q15: #REF! | R15: =FINV(C15,0.4, 0.3) -> #NUM! | S15: =FINV(D15,9,34) -> 1.8224283 | T15: =FINV(0.4,E15,32) -> #NUM! | U15: =FINV(0.01, F15,2) -> 99.489163 | V15: =FINV(D15,G15,32) -> 2.1292876 | W15: =FINV(H15,3,33) -> #NUM! | X15: =FINV(0.9,I15,33) -> 0.51329505 | Y15: =FINV(0.3,J15,12) -> 1.173347 | Z15: =FINV(K15,C15,32) -> #VALUE! | AA15: =FINV(L15,D15,32) -> #N/A | AB15: =FINV(M15,E15,32) -> #DIV/0! | AC15: =FINV(N15,F15,32) -> #NAME? | AD15: =FINV(O15,G15,32) -> #NULL! | AE15: =FINV(P15,H15,32) -> #NUM! | AF15: =FINV(Q15,I15,32) -> #REF! | AG15: {=FINV(0.6, C15:Q15, 12)} -> 0.84453369 | AH15: {=FINV(0.5, C15:Q15, 120)} -> 0.93942399 | AI15: #NUM! | AJ15: #NUM! | AK15: 0.99888544 | AL15: 0.84393491 | AM15: #NUM! | AN15: 0.95453042 | AO15: 0.457706 | AP15: #VALUE! | AQ15: #N/A | AR15: #DIV/0! | AS15: #NAME? | AT15: #NULL! | AU15: #NUM! | AV15: #REF! | AW15: #N/A
A16: FLOOR | B16: DONE | C16: 2.5 | D16: -255.5 | E16: -2.5 | F16: 1.5 | G16: 0.234 | I16: ciao | J16: TRUE | K16: #VALUE! | L16: #N/A | M16: #DIV/0! | N16: #NAME? | O16: #NULL! | P16: #NUM! | Q16: #REF! | R16: =FLOOR(C16,1) -> 2 | S16: =FLOOR(D16,-2) -> -254 | T16: =FLOOR(E16,2) -> -4 | U16: =FLOOR(F16,0) -> #DIV/0! | V16: =FLOOR(G16,0.01) -> 0.23 | W16: =FLOOR(H16,-2) -> 0 | X16: =FLOOR(I16,0) -> #VALUE! | Y16: =FLOOR(J16,0) -> #DIV/0! | Z16: =FLOOR(2.3,K16) -> #VALUE! | AA16: =FLOOR(2.3,L16) -> #N/A | AB16: =FLOOR(2.3,M16) -> #DIV/0! | AC16: =FLOOR(2.3,N16) -> #NAME? | AD16: =FLOOR(2.3,O16) -> #NULL! | AE16: =FLOOR(2.3,P16) -> #NUM! | AF16: =FLOOR(2.3,Q16) -> #REF! | AH16: {=FLOOR(C16:P16,D16:Q16)} -> #NUM! | AI16: -255 | AJ16: -3 | AK16: 1.404 | AL16: #DIV/0! | AM16: #VALUE! | AN16: #VALUE! | AO16: #VALUE! | AP16: #VALUE! | AQ16: #N/A | AR16: #DIV/0! | AS16: #NAME? | AT16: #NULL! | AU16: #NUM! | AV16: #N/A | AW16: #N/A
A17: FTEST | B17: DONE | C17: 10 | D17: 3.2 | E17: 0.7 | F17: 2 | G17: 4 | I17: 13/01/1900 | J17: TRUE | K17: #VALUE! | L17: #N/A | M17: #DIV/0! | N17: #NAME? | O17: #NULL! | P17: #NUM! | Q17: #REF! | R17: =FTEST(C16:D17,E14:E17) -> 6.2687798e-06 | S17: =FTEST(D17:E17,E17:G17) -> 0.7979982 | T17: =FTEST(E17:F17,G17:H17) -> #DIV/0! | U17: =FTEST(D17,F17) -> #DIV/0! | V17: =FTEST(G17:I17,H17:J17) -> #DIV/0! | W17: =FTEST(H17:I17,J17:K17) -> #VALUE! | X17: =FTEST(I17:J17,K17:L17) -> #VALUE! | Y17: =FTEST(J17:K17,L17:M17) -> #VALUE! | Z17: =FTEST(K17:L17,M17:N17) -> #VALUE! | AA17: =FTEST(L17:M17,N17:O17) -> #N/A | AB17: =FTEST(M17:N17,O17:P17) -> #DIV/0! | AC17: =FTEST(N17:O17,P17:Q17) -> #NAME? | AD17: =FTEST(O17:P17,Q17:R17) -> #NUM! | ... AF17: =FTEST(Q17:R17,S17:T17) -> #REF! | AG17: {=FTEST(C16:D17, F16:G17)} -> 5.8704555e-06 | AH17: {=FTEST(D17:E17, E17:F17)} -> 0.61054293 | AI17: 0.61054293 | AJ17: 0.61054293 | AK17: 0.61054293 | AL17: 0.61054293 | AM17: 0.61054293 | AN17: 0.61054293 | AO17: 0.61054293 | AP17: 0.61054293 | AQ17: 0.61054293 | AR17: 0.61054293 | AS17: 0.61054293 | AT17: 0.61054293 | AU17: 0.61054293 | AV17: 0.61054293 | AW17: 0.61054293
A18: GAMMADIST | B18: DONE | C18: 0 | D18: 5 | E18: 0.7 | F18: 3 | G18: 4 | I18: 29/02/1900 | J18: TRUE | K18: #VALUE! | L18: #N/A | M18: #DIV/0! | N18: #NAME? | O18: #NULL! | P18: #NUM! | Q18: #REF! | R18: =GAMMADIST(C18,,,) -> #NUM! | S18: =GAMMADIST(D18,10,30,FALSE) -> 7.7156416e-15 | T18: =GAMMADIST(E18,"1",5, 3) -> 0.13064176 | U18: =GAMMADIST(F18,-1,3,"TRUE") -> #NUM! | V18: =GAMMADIST(G18, 7,4,1) -> 8.3241149e-05 | W18: =GAMMADIST(H18,H18,4,1) -> #NUM! | X18: =GAMMADIST(I18,I18,4,1) -> 1.7894866e-18 | Y18: =GAMMADIST(J18,I18,32,1) -> 5.7210704e-173 | Z18: =GAMMADIST(K18,I18,3,1) -> #VALUE! | AA18: =GAMMADIST(L18,J18,3,1) -> #N/A | AB18: =GAMMADIST(M18,K18,3,1) -> #DIV/0! | AC18: =GAMMADIST(N18,L18,3,1) -> #NAME? | AD18: =GAMMADIST(O18,M18,3,1) -> #NULL! | AE18: =GAMMADIST(P18,N18,3,1) -> #NUM! | AF18: =GAMMADIST(Q18,O18,3,1) -> #REF! | AG18: {=GAMMADIST(C18:Q18,3,3,1)} -> 0 | AH18: {=GAMMADIST(C18:Q18,1,3,1)} -> 0 | AI18: 0.8111244 | AJ18: 0.20811043 | AK18: 0.63212056 | AL18: 0.73640286 | AM18: 0 | AN18: 1 | AO18: 0.28346869 | AP18: #VALUE! | AQ18: #N/A | AR18: #DIV/0! | AS18: #NAME? | AT18: #NULL! | AU18: #NUM! | AV18: #REF! | AW18: #N/A
A19: GAMMAINV | B19: DONE | C19: 10 | D19: 0.1 | E19: 0.7 | F19: 100 | G19: 4 | I19: 13/01/1900 | J19: TRUE | K19: #VALUE! | L19: #N/A | M19: #DIV/0! | N19: #NAME? | O19: #NULL! | P19: #NUM! | Q19: #REF! | R19: =GAMMAINV(C19,0.4,3) -> #NUM! | S19: =GAMMAINV(D19,90,9) -> 702.68682 | T19: =GAMMAINV(0.4,E19, 32) -> 8.8217624 | U19: =GAMMAINV(0.01, F19,2) -> 156.43197 | V19: =GAMMAINV(D19,G19,32) -> 55.832626 | W19: =GAMMAINV(H19,3, 2.22) -> 0 | X19: =GAMMAINV(0.9,I19,781) -> 13887.418 | Y19: =GAMMAINV(0.3,J19, 332) -> 118.41608 | Z19: =GAMMAINV(K19,C19, 21) -> #VALUE! | AA19: =GAMMAINV(L19,D19, 21) -> #N/A | AB19: =GAMMAINV(M19,E19, 21) -> #DIV/0! | AC19: =GAMMAINV(N19,F19, 21) -> #NAME? | AD19: =GAMMAINV(O19,G19, 21) -> #NULL! | AE19: =GAMMAINV(P19,H19, 21) -> #NUM! | AF19: =GAMMAINV(Q19,I19, 21) -> #REF! | AG19: {=GAMMAINV(0.6, C19:Q19,32)} -> 335.22189 | AH19: {=GAMMAINV(0.5, C19:Q19, 23)} -> 222.38044 | AI19: 0.013647995 | AJ19: 9.3707462 | AK19: 2292.3379 | AL19: 84.457397 | AM19: #NUM! | AN19: 291.36927 | AO19: 15.942385 | AP19: #VALUE! | AQ19: #N/A | AR19: #DIV/0! | AS19: #NAME? | AT19: #NULL! | AU19: #NUM! | AV19: #REF! | AW19: #N/A
A20: HYPGEOMDIST | B20: DONE | C20: 0 | D20: 5 | E20: 0.7 | F20: 3 | G20: 4 | I20: 29/02/1900 | J20: TRUE | K20: #VALUE! | L20: #N/A | M20: #DIV/0! | N20: #NAME? | O20: #NULL! | P20: #NUM! | Q20: #REF! | R20: =HYPGEOMDIST(C20,,,) -> 1 | S20: =HYPGEOMDIST(D20,10,30,7) -> #NUM! | T20: =HYPGEOMDIST(E20,"1",5,8) -> 0.375 | U20: =HYPGEOMDIST(F20,-1,3,5) -> #NUM! | V20: =HYPGEOMDIST(G20,3, 7,4) -> #NUM! | W20: =HYPGEOMDIST(H20,H20,4,4) -> 1 | X20: =HYPGEOMDIST(I20,I20,4,4) -> #NUM! | Y20: =HYPGEOMDIST(J20,I20,45,32) -> #NUM! | Z20: =HYPGEOMDIST(K20,I20,3,3) -> #VALUE! | AA20: =HYPGEOMDIST(L20,J20,3,3) -> #N/A | AB20: =HYPGEOMDIST(M20,K20,3,3) -> #DIV/0! | AC20: =HYPGEOMDIST(N20,L20,3,3) -> #NAME? | AD20: =HYPGEOMDIST(O20,M20,3,3) -> #NULL! | AE20: =HYPGEOMDIST(P20,N20,3,3) -> #NUM! | AF20: =HYPGEOMDIST(Q20,O20,3,3) -> #REF! | AG20: {=HYPGEOMDIST(C20:Q20,2,3,3)} -> 0 | AH20: {=HYPGEOMDIST(C20:Q20, 3,2,30)} -> 0.80689655 | AI20: 0 | AJ20: 0.80689655 | AK20: 0 | AL20: 0 | AM20: 0.80689655 | AN20: 0 | AO20: 0.1862069 | AP20: #VALUE! | AQ20: #N/A | AR20: #DIV/0! | AS20: #NAME? | AT20: #NULL! | AU20: #NUM! | AV20: #REF! | AW20: #N/A
A21: LOGINV | B21: DONE | C21: 0 | D21: 0.1 | E21: 0.7 | F21: 0.002 | G21: 4 | I21: 13/01/1900 | J21: TRUE | K21: #VALUE! | L21: #N/A | M21: #DIV/0! | N21: #NAME? | O21: #NULL! | P21: #NUM! | Q21: #REF! | R21: =LOGINV(C21,4,4) -> #NUM! | S21: =LOGINV(D21,2,2) -> 0.56943927 | T21: =LOGINV(0.4,2,E21) -> 6.1882791 | U21: =LOGINV(F21,4,3) -> 0.0097111049 | V21: =LOGINV(G21,D21,E21) -> #NUM! | W21: =LOGINV(H21,3,2) -> #NUM! | X21: =LOGINV(0.9,I21, 1) -> 1593672.4 | Y21: =LOGINV(0.3,J21,2) -> 0.95237061 | Z21: =LOGINV(K21,C21,E21) -> #VALUE! | AA21: =LOGINV(L21,D21,F21) -> #N/A | AB21: =LOGINV(M21,E21,G21) -> #DIV/0! | AC21: =LOGINV(N21,F21,H21) -> #NAME? | AD21: =LOGINV(O21,G21,I21) -> #NULL! | AE21: =LOGINV(P21,H21,J21) -> #NUM! | AF21: =LOGINV(Q21,I21,K21) -> #REF! | AG21: {=LOGINV(C21:Q21,3,3)} -> #NUM! | AH21: {=LOGINV(C21:Q21, 3,2)} -> #NUM! | AI21: 1.5478964 | AJ21: 57.32868 | AK21: 0.06352489 | AL21: #NUM! | AM21: #NUM! | AN21: #NUM! | AO21: #NUM! | AP21: #VALUE! | AQ21: #N/A | AR21: #DIV/0! | AS21: #NAME? | AT21: #NULL! | AU21: #NUM! | AV21: #REF! | AW21: #N/A
A22: LOGNORMDIST | B22: DONE | C22: 0 | D22: 5 | E22: 0.7 | F22: 3 | G22: 4 | I22: 29/02/1900 | J22: TRUE | K22: #VALUE! | L22: #N/A | M22: #DIV/0! | N22: #NAME? | O22: #NULL! | P22: #NUM! | Q22: #REF! | R22: =LOGNORMDIST(C22,,) -> #NUM! | S22: =LOGNORMDIST(D22,1,2) -> 0.61970989 | T22: =LOGNORMDIST(E22,"1","3") -> 0.32555346 | U22: =LOGNORMDIST(F22,-1,2) -> 0.85298138 | V22: =LOGNORMDIST(G22, 0,0) -> #NUM! | W22: =LOGNORMDIST(H22,H22,G22) -> #NUM! | X22: =LOGNORMDIST(I22,,I22) -> 0.52720234 | Y22: =LOGNORMDIST(J22,I22,E22) -> 0 | Z22: =LOGNORMDIST(K22,I22,G22) -> #VALUE! | AA22: =LOGNORMDIST(L22,J22,H22) -> #N/A | AB22: =LOGNORMDIST(M22,K22,I22) -> #DIV/0! | AC22: =LOGNORMDIST(N22,L22,J22) -> #NAME? | AD22: =LOGNORMDIST(O22,M22,K22) -> #NULL! | AE22: =LOGNORMDIST(P22,N22,L22) -> #NUM! | AF22: =LOGNORMDIST(Q22,O22,M22) -> #REF! | AG22: {=LOGNORMDIST(C22:Q22,3,3)} -> #NUM! | AH22: {=LOGNORMDIST(C22:Q22,3,4)} -> #NUM! | AI22: 0.36405509 | AJ22: 0.20068731 | AK22: 0.31726986 | AL22: 0.34331728 | AM22: #NUM! | AN22: 0.60779866 | AO22: 0.22662735 | AP22: #VALUE! | AQ22: #N/A | AR22: #DIV/0! | AS22: #NAME? | AT22: #NULL! | AU22: #NUM! | AV22: #REF! | AW22: #N/A
A23: MODE | B23: DONE | C23: 0 | D23: 0.1 | E23: 0.2 | F23: 0.3 | G23: -0.1 | I23: 29/02/1900 | J23: TRUE | K23: #VALUE! | L23: #N/A | M23: #DIV/0! | N23: #NAME? | O23: #NULL! | P23: #NUM! | Q23: #REF! | R23: =MODE(C23:D23,D23:E23,E23:F23) -> 0.1 | S23: =MODE(D23:E23,E23:F23,F23:G23,"") -> 0.2 | T23: =MODE(E23:F23,F23:G23,G23:H23,"29/02/1900") -> 0.3 | U23: =MODE(F23:G23,G23:H23,H23:I23) -> -0.1 | V23: =MODE(G23:H23,H23:I23,I23:J23) -> #N/A | W23: =MODE(G23:H23) -> #N/A | X23: =MODE(I23,G23) -> #N/A | Y23: =MODE(J23,G23) -> #N/A | Z23: =MODE(K23:L23) -> #VALUE! | AA23: =MODE(L23:M23) -> #N/A | AB23: =MODE(M23:N23) -> #DIV/0! | AC23: =MODE(N23:O23) -> #NAME? | AD23: =MODE(O23:P23) -> #NULL! | AE23: =MODE(P23:Q23) -> #NUM! | AF23: =MODE(Q23:R23) -> #REF! | AG23: {=MODE(H23:J23)} -> #N/A | AH23: {=MODE(C23:J23,D23:F23,E23:G23)} -> 0.2 | AI23: 0.2 | AJ23: 0.2 | AK23: 0.2 | AL23: 0.2 | AM23: 0.2 | AN23: 0.2 | AO23: 0.2 | AP23: 0.2 | AQ23: 0.2 | AR23: 0.2 | AS23: 0.2 | AT23: 0.2 | AU23: 0.2 | AV23: 0.2 | AW23: 0.2
A24: NEGBINOMDIST | B24: DONE | C24: 0 | D24: 5 | E24: 0.7 | F24: 3 | G24: 4 | I24: 29/02/1900 | J24: TRUE | K24: #VALUE! | L24: #N/A | M24: #DIV/0! | N24: #NAME? | O24: #NULL! | P24: #NUM! | Q24: #REF! | R24: =NEGBINOMDIST(C24,,) -> #NUM! | S24: =NEGBINOMDIST(D24,10,0.2) -> 6.7175973e-05 | T24: =NEGBINOMDIST(E24,"1",".3") -> 0.3 | U24: =NEGBINOMDIST(F24,-1,0.2) -> #NUM! | V24: =NEGBINOMDIST(G24, 7,0.4) -> 0.044590694 | W24: =NEGBINOMDIST(H24,H24,G24/7) -> #NUM! | X24: =NEGBINOMDIST(I24,I24,) -> #NUM! | Y24: =NEGBINOMDIST(J24,I24,E24) -> 9.1443935e-09 | Z24: =NEGBINOMDIST(K24,I24,G24) -> #VALUE! | AA24: =NEGBINOMDIST(L24,J24,H24) -> #N/A | AB24: =NEGBINOMDIST(M24,K24,I24) -> #DIV/0! | AC24: =NEGBINOMDIST(N24,L24,J24) -> #NAME? | AD24: =NEGBINOMDIST(O24,M24,K24) -> #NULL! | AE24: =NEGBINOMDIST(P24,N24,L24) -> #NUM! | AF24: =NEGBINOMDIST(Q24,O24,M24) -> #REF! | AG24: {=NEGBINOMDIST(C24:Q24,3,0.3)} -> 0.027 | AH24: {=NEGBINOMDIST(C24:Q24,3,0.4)} -> 0.064 | AI24: 0.10450944 | AJ24: 0.064 | AK24: 0.13824 | AL24: 0.124416 | AM24: 0.064 | AN24: 5.914888e-12 | AO24: 0.1152 | AP24: #VALUE! | AQ24: #N/A | AR24: #DIV/0! | AS24: #NAME? | AT24: #NULL! | AU24: #NUM! | AV24: #REF! | AW24: #N/A
A25: NORM.INV | B25: DONE | C25: 0 | D25: -0.1 | E25: 0.7 | F25: 0.002 | G25: 4 | I25: 29/02/1900 | J25: TRUE | K25: #VALUE! | L25: #N/A | M25: #DIV/0! | N25: #NAME? | O25: #NULL! | P25: #NUM! | Q25: #REF! | R25: =_xlfn.NORM.INV(C25,4,4) -> #NUM! | S25: =_xlfn.NORM.INV(D25,2,2) -> #NUM! | T25: =_xlfn.NORM.INV(0.4,2,E25) -> 1.822657 | U25: =_xlfn.NORM.INV(F25,4,3) -> -4.6344852 | V25: =_xlfn.NORM.INV(G25,D25,E25) -> #NUM! | W25: =_xlfn.NORM.INV(H25,3,2) -> #NUM! | X25: =_xlfn.NORM.INV(0.3,I25,2) -> 58.951199 | Y25: =_xlfn.NORM.INV(0.3,J25,2) -> -0.048801025 | Z25: =_xlfn.NORM.INV(K25,C25,E25) -> #VALUE! | AA25: =_xlfn.NORM.INV(L25,D25,F25) -> #N/A | AB25: =_xlfn.NORM.INV(M25,E25,G25) -> #DIV/0! | AC25: =_xlfn.NORM.INV(N25,F25,H25) -> #NAME? | AD25: =_xlfn.NORM.INV(O25,G25,I25) -> #NULL! | AE25: =_xlfn.NORM.INV(P25,H25,J25) -> #NUM! | AF25: =_xlfn.NORM.INV(Q25,I25,K25) -> #REF! | AG25: {=_xlfn.NORM.INV(C25:Q25,3,3)} -> #NUM! | AH25: {=_xlfn.NORM.INV(C25:Q25, 3,2)} -> #NUM! | AI25: #NUM! | AJ25: 4.048801 | AK25: -2.7563235 | AL25: #NUM! | AM25: #NUM! | AN25: #NUM! | AO25: #NUM! | AP25: #VALUE! | AQ25: #N/A | AR25: #DIV/0! | AS25: #NAME? | AT25: #NULL! | AU25: #NUM! | AV25: #REF! | AW25: #N/A
A26: NORMDIST | B26: DONE | C26: 0 | D26: -0.1 | E26: 0.7 | F26: 3 | G26: 4 | I26: 29/02/1900 | J26: TRUE | K26: #VALUE! | L26: #N/A | M26: #DIV/0! | N26: #NAME? | O26: #NULL! | P26: #NUM! | Q26: #REF! | R26: =NORMDIST(C26,,,) -> #NUM! | S26: =NORMDIST(D26,1,2,FALSE) -> 0.17147193 | T26: =NORMDIST(E26,"1","3",5) -> 0.46017216 | U26: =NORMDIST(F26,-1,2,"TRUE") -> 0.97724987 | V26: =NORMDIST(G26, 0,0,1) -> #NUM! | W26: =NORMDIST(H26,H26,G26,1) -> 0.5 | X26: =NORMDIST(I26,,I26,1) -> 0.84134475 | Y26: =NORMDIST(J26,I26,E26,1) -> 0 | Z26: =NORMDIST(K26,I26,G26,1) -> #VALUE! | AA26: =NORMDIST(L26,J26,H26,1) -> #N/A | AB26: =NORMDIST(M26,K26,I26,1) -> #DIV/0! | AC26: =NORMDIST(N26,L26,J26,1) -> #NAME? | AD26: =NORMDIST(O26,M26,K26,1) -> #NULL! | AE26: =NORMDIST(P26,N26,L26,1) -> #NUM! | AF26: =NORMDIST(Q26,O26,M26,1) -> #REF! | AG26: {=NORMDIST(C26:Q26,3,3,1)} -> 0.15865525 | AH26: {=NORMDIST(C26:Q26,C26:Q26,4,1)} -> 0.5 | AI26: 0.5 | AJ26: 0.5 | AK26: 0.5 | AL26: 0.5 | AM26: 0.5 | AN26: 0.5 | AO26: 0.5 | AP26: #VALUE! | AQ26: #N/A | AR26: #DIV/0! | AS26: #NAME? | AT26: #NULL! | AU26: #NUM! | AV26: #REF! | AW26: #N/A
A27: NORMSDIST | B27: DONE | C27: 0 | D27: -0.1 | E27: 0.7 | F27: 3 | G27: 4 | I27: 29/02/1900 | J27: TRUE | K27: #VALUE! | L27: #N/A | M27: #DIV/0! | N27: #NAME? | O27: #NULL! | P27: #NUM! | Q27: #REF! | R27: =NORMSDIST(C27) -> 0.5 | S27: =NORMSDIST(D27) -> 0.46017216 | T27: =NORMSDIST(E27) -> 0.75803635 | U27: =NORMSDIST(F27) -> 0.9986501 | V27: =NORMSDIST(G27) -> 0.99996833 | W27: =NORMSDIST(H27) -> 0.5 | X27: =NORMSDIST(I27) -> 1 | Y27: =NORMSDIST(J27) -> 0.84134475 | ... AF27: =NORMSDIST(Q27) -> #REF! | AG27: {=NORMSDIST(C27:Q27)} -> 0.5 | AH27: {=NORMSDIST(C27:Q27)} -> 0.5 | AI27: 0.46017216 | AJ27: 0.75803635 | AK27: 0.9986501 | AL27: 0.99996833 | AM27: 0.5 | AN27: 1 | AO27: 0.84134475 | AP27: #VALUE! | AQ27: #N/A | AR27: #DIV/0! | AS27: #NAME? | AT27: #NULL! | AU27: #NUM! | AV27: #REF! | AW27: #N/A
A28: NORMSINV | B28: DONE | C28: 0 | D28: -0.1 | E28: 0.7 | F28: 0.002 | G28: 4 | I28: 29/02/1900 | J28: TRUE | K28: #VALUE! | L28: #N/A | M28: #DIV/0! | N28: #NAME? | O28: #NULL! | P28: #NUM! | Q28: #REF! | R28: =NORMSINV(C28) -> #NUM! | S28: =NORMSINV(D28) -> #NUM! | T28: =NORMSINV(E28) -> 0.52440051 | U28: =NORMSINV(F28) -> -2.8781617 | V28: =NORMSINV(G28) -> #NUM! | W28: =NORMSINV(H28) -> #NUM! | X28: =NORMSINV(I28) -> #NUM! | Y28: =NORMSINV(J28) -> #NUM! | ... AF28: =NORMSINV(Q28) -> #REF! | AG28: {=NORMSINV(C28:Q28)} -> #NUM! | AH28: {=NORMSINV(C28:Q28)} -> #NUM! | AI28: #NUM! | AJ28: 0.52440051 | AK28: -2.8781617 | AL28: #NUM! | AM28: #NUM! | AN28: #NUM! | AO28: #NUM! | AP28: #VALUE! | AQ28: #N/A | AR28: #DIV/0! | AS28: #NAME? | AT28: #NULL! | AU28: #NUM! | AV28: #REF! | AW28: #N/A
A29: PERCENTILE | B29: DONE | C29: 0 | D29: -10 | E29: 0.9 | F29: 0.1 | G29: -0.1 | I29: 1/01/1900 | J29: TRUE | K29: #VALUE! | L29: #N/A | M29: #DIV/0! | N29: #NAME? | O29: #NULL! | P29: #NUM! | Q29: #REF! | R29: =PERCENTILE(C29:D29,".2") -> -8 | S29: =PERCENTILE(C29:H29,E29) -> 0.58 | T29: =PERCENTILE(E29:F29,F29) -> 0.18 | U29: =PERCENTILE(F29:G29,G29) -> #NUM! | V29: =PERCENTILE(G29:H29,H29) -> -0.1 | W29: =PERCENTILE(D29:E29,I29) -> 0.9 | X29: =PERCENTILE(E29:I29,J29) -> 0.9 | Y29: =PERCENTILE(I29:J29,K29) -> #VALUE! | Z29: =PERCENTILE(K29:L29,L29) -> #N/A | AA29: =PERCENTILE(L29:M29,M29) -> #DIV/0! | AB29: =PERCENTILE(M29:N29,N29) -> #NAME? | AC29: =PERCENTILE(N29:O29,O29) -> #NULL! | AD29: =PERCENTILE(O29:P29,P29) -> #NUM! | AE29: =PERCENTILE(P29:Q29,Q29) -> #REF! | AF29: =PERCENTILE(Q29:R29,R29) -> #REF! | AG29: {=PERCENTILE(C29:G29,0.03)} -> -8.812 | AH29: {=PERCENTILE(C29:J29,C29:Q29)} -> -10 | AI29: #NUM! | AJ29: 0.58 | AK29: -6.04 | AL29: #NUM! | AM29: -10 | AN29: 0.9 | AO29: 0.9 | AP29: #VALUE! | AQ29: #N/A | AR29: #DIV/0! | AS29: #NAME? | AT29: #NULL! | AU29: #NUM! | AV29: #REF! | AW29: #N/A
A30: PERCENTRANK | B30: DONE | C30: 0 | D30: 0.1 | E30: 0.7 | F30: 0.002 | G30: 4 | I30: 13/01/1900 | J30: TRUE | K30: #VALUE! | L30: #N/A | M30: #DIV/0! | N30: #NAME? | O30: #NULL! | P30: #NUM! | Q30: #REF! | R30: =PERCENTRANK(C30:J30,4,4) -> 1 | S30: =PERCENTRANK(C30:I30,2,2) -> 0.84 | T30: =PERCENTRANK(C30:I30,2,E30) -> #NUM! | U30: =PERCENTRANK(C30:I30,4,3) -> 1 | V30: =PERCENTRANK(C30:I30,D30,E30) -> #NUM! | W30: =PERCENTRANK(C30:I30,3,2) -> 0.92 | X30: =PERCENTRANK(C30:I30,I30, 1) -> #N/A | Y30: {=PERCENTRANK(C30:I30,J30,2)} -> 0.77 | Z30: 0.77 | AA30: 0.77 | AB30: 0.77 | AC30: 0.77 | AD30: 0.77 | AE30: 0.77 | AF30: 0.77 | AG30: 0.77 | AH30: 0.77 | AI30: 0.77 | AJ30: 0.77 | AK30: 0.77 | AL30: 0.77 | AM30: 0.77 | AN30: 0.77 | AO30: 0.77 | AP30: 0.77 | AQ30: 0.77 | AR30: 0.77 | AS30: 0.77 | AT30: 0.77 | AU30: 0.77 | AV30: 0.77 | AW30: 0.77
A31: POISSON | B31: DONE | C31: 0 | D31: 5 | E31: 0.7 | F31: 3 | G31: 4 | I31: 29/02/1900 | J31: TRUE | K31: #VALUE! | L31: #N/A | M31: #DIV/0! | N31: #NAME? | O31: #NULL! | P31: #NUM! | Q31: #REF! | R31: =POISSON(C31,,) -> 1 | S31: =POISSON(D31,10,FALSE) -> 0.037833275 | T31: =POISSON(E31,"1",5) -> 0.36787944 | U31: =POISSON(F31,-1,"TRUE") -> #NUM! | V31: =POISSON(G31, 7,1) -> 0.17299161 | W31: =POISSON(H31,H31,1) -> 1 | X31: =POISSON(I31,I31,1) -> 0.53426247 | Y31: =POISSON(J31,I31,1) -> 5.3414716e-25 | Z31: =POISSON(K31,I31,1) -> #VALUE! | AA31: =POISSON(L31,J31,1) -> #N/A | AB31: =POISSON(M31,K31,1) -> #DIV/0! | AC31: =POISSON(N31,L31,1) -> #NAME? | AD31: =POISSON(O31,M31,1) -> #NULL! | AE31: =POISSON(P31,N31,1) -> #NUM! | AF31: =POISSON(Q31,O31,1) -> #REF! | AG31: {=POISSON(C31:Q31,3,1)} -> 0.049787068 | AH31: {=POISSON(C31:Q31,3,1)} -> 0.049787068 | AI31: 0.91608206 | AJ31: 0.049787068 | AK31: 0.64723189 | AL31: 0.81526324 | AM31: 0.049787068 | AN31: 1 | AO31: 0.19914827 | AP31: #VALUE! | AQ31: #N/A | AR31: #DIV/0! | AS31: #NAME? | AT31: #NULL! | AU31: #NUM! | AV31: #REF! | AW31: #N/A
A32: QUARTILE | B32: DONE | C32: 0 | D32: -10 | E32: 0.9 | F32: 2.2 | G32: -0.1 | I32: 1/01/1900 | J32: TRUE | K32: #VALUE! | L32: #N/A | M32: #DIV/0! | N32: #NAME? | O32: #NULL! | P32: #NUM! | Q32: #REF! | R32: =QUARTILE(C32:D32,"2") -> -5 | S32: =QUARTILE(C32:H32,E32) -> -10 | T32: =QUARTILE(E32:F32,F32) -> 1.55 | U32: =QUARTILE(F32:G32,G32) -> #NUM! | V32: =QUARTILE(G32:H32,H32) -> -0.1 | W32: =QUARTILE(D32:E32,I32) -> -7.275 | X32: =QUARTILE(E32:I32,J32) -> 0.4 | Y32: =QUARTILE(I32:J32,K32) -> #VALUE! | Z32: =QUARTILE(K32:L32,L32) -> #N/A | AA32: =QUARTILE(L32:M32,I32) -> #N/A | AB32: =QUARTILE(M32:N32,N32) -> #NAME? | AC32: =QUARTILE(N32:O32,O32) -> #NULL! | AD32: =QUARTILE(O32:P32,P32) -> #NUM! | AE32: =QUARTILE(P32:Q32,Q32) -> #REF! | AF32: =QUARTILE(Q32:R32,R32) -> #REF! | AG32: =QUARTILE(C32:G32,I32) -> -0.1 | AH32: {=QUARTILE(C32:J32,C32:Q32)} -> -10 | AI32: #NUM! | AJ32: -10 | AK32: 0 | AL32: #NUM! | AM32: -10 | AN32: -0.1 | AO32: -0.1 | AP32: #VALUE! | AQ32: #N/A | AR32: #DIV/0! | AS32: #NAME? | AT32: #NULL! | AU32: #NUM! | AV32: #REF! | AW32: #N/A
A33: RANK | B33: DONE | C33: 0 | D33: -10 | E33: 0 | F33: 2.2 | G33: -0.1 | I33: 1/01/1901 | J33: TRUE | K33: #VALUE! | L33: #N/A | M33: #DIV/0! | N33: #NAME? | O33: #NULL! | P33: #NUM! | Q33: #REF! | R33: =RANK(2,C33:F33,1) -> #N/A | S33: =RANK(0,C33:J33,1) -> 3 | T33: =RANK(F33,C33:J33,0) -> 1 | U33: =RANK(G33,C33:J33,0) -> 4 | V33: =RANK(D33,C33:J33,1) -> 1 | W33: =RANK(H33,C33:J33,1) -> 3 | X33: =RANK(I33,C33:J33,1) -> #N/A | Y33: =RANK(J33,C33:J33,1) -> #N/A | Z33: =RANK(K33,D33:K33,1) -> #VALUE! | AA33: =RANK(L33,E33:L33,1) -> #N/A | AB33: =RANK(M33,F33:M33,1) -> #DIV/0! | AC33: =RANK(N33,G33:N33,1) -> #NAME? | AD33: =RANK(O33,H33:O33,1) -> #NULL! | AE33: =RANK(P33,I33:P33,1) -> #NUM! | AF33: =RANK(Q33,J33:Q33,1) -> #REF! | AG33: {=RANK(C33:H33,C33:J33,1)} -> 3 | AH33: {=RANK(C33:Q33,C33:J33,1)} -> 3 | AI33: 1 | AJ33: 3 | AK33: 5 | AL33: 2 | AM33: 3 | AN33: #N/A | AO33: #N/A | AP33: #VALUE! | AQ33: #N/A | AR33: #DIV/0! | AS33: #NAME? | AT33: #NULL! | AU33: #NUM! | AV33: #REF! | AW33: #N/A
A34: STDEV | B34: DONE | C34: 0 | D34: -10 | E34: 0.9 | F34: 2.2 | G34: -0.1 | I34: 1/01/1900 | J34: TRUE | K34: #VALUE! | L34: #N/A | M34: #DIV/0! | N34: #NAME? | O34: #NULL! | P34: #NUM! | Q34: #REF! | R34: =STDEV(C34:D34,D34:E34,E34:F34,"2") -> 5.5145263 | S34: =STDEV(D34:E34,E34:F34,F34:G34,"") -> #VALUE! | T34: =STDEV(E34:F34,F34:G34,G34:H34,"29/02/1900") -> 24.100519 | U34: =STDEV(G34:H34) -> #DIV/0! | V34: =STDEV(F34:H34,H34:I34,I34:J34) -> 1.6263456 | W34: =STDEV(G34:H34) -> #DIV/0! | X34: =STDEV(I34,G34,E34) -> 0.70710678 | Y34: =STDEV(J34,G34) -> #DIV/0! | Z34: =STDEV(K34:L34) -> #VALUE! | AA34: =STDEV(L34:M34) -> #N/A | AB34: =STDEV(M34:N34) -> #DIV/0! | AC34: =STDEV(N34:O34) -> #NAME? | AD34: =STDEV(O34:P34) -> #NULL! | AE34: =STDEV(P34:Q34) -> #NUM! | AF34: =STDEV(Q34:R34) -> #REF! | AG34: =STDEV(F34:J34) -> 1.6263456 | AH34: {=STDEV(C34:J34)} -> 4.895406 | AI34: 4.895406 | AJ34: 4.895406 | AK34: 4.895406 | AL34: 4.895406 | AM34: 4.895406 | AN34: {=STDEV(J34:Q34)} -> #VALUE! | AO34: #VALUE! | AP34: #VALUE! | AQ34: #VALUE! | AR34: #VALUE! | AS34: #VALUE! | AT34: #VALUE! | AU34: #VALUE! | AV34: #VALUE! | AW34: #VALUE!
A35: STDEVP | B35: DONE | C35: 0 | D35: -10 | E35: 0.9 | F35: 2.2 | G35: -0.1 | I35: 1/01/1900 | J35: TRUE | K35: #VALUE! | L35: #N/A | M35: #DIV/0! | N35: #NAME? | O35: #NULL! | P35: #NUM! | Q35: #REF! | R35: =STDEVP(C35:D35,D35:E35,E35:F35,"2") -> 5.1054593 | S35: =STDEVP(D35:E35,E35:F35,F35:G35,"") -> #VALUE! | T35: =STDEVP(E35:F35,F35:G35,G35:H35,"29/02/1900") -> 22.000663 | U35: =STDEVP(H35) -> #DIV/0! | V35: =STDEVP(G35:H35,H35:I35,I35:J35) -> 0 | W35: =STDEVP(G35:H35) -> 0 | X35: =STDEVP(I35,G35) -> 0 | Y35: =STDEVP(J35,G35) -> 0 | Z35: =STDEVP(K35:L35) -> #VALUE! | AA35: =_xlfn.STDEV.P(L35:M35) -> #N/A | AB35: =STDEVP(M35:N35) -> #DIV/0! | AC35: =STDEVP(N35:O35) -> #NAME? | AD35: =STDEVP(O35:P35) -> #NULL! | AE35: =STDEVP(P35:Q35) -> #NUM! | AF35: =STDEVP(Q35:R35) -> #REF! | AG35: =STDEVP(F35:J35) -> 1.15 | AH35: {=STDEVP(C35:J35)} -> 4.3785842 | AI35: 4.3785842 | AJ35: 4.3785842 | AK35: 4.3785842 | AL35: 4.3785842 | AM35: 4.3785842 | AN35: {=STDEVP(J35:Q35)} -> #VALUE! | AO35: #VALUE! | AP35: #VALUE! | AQ35: #VALUE! | AR35: #VALUE! | AS35: #VALUE! | AT35: #VALUE! | AU35: #VALUE! | AV35: #VALUE! | AW35: #VALUE!
A36: TDIST | B36: DONE | C36: 0 | D36: 5 | E36: 0.7 | F36: 3 | G36: 4 | I36: 29/02/1900 | J36: TRUE | K36: #VALUE! | L36: #N/A | M36: #DIV/0! | N36: #NAME? | O36: #NULL! | P36: #NUM! | Q36: #REF! | R36: =TDIST(C36,,) -> #NUM! | S36: =TDIST(D36,10,2) -> 0.0005373336 | T36: =TDIST(E36,1,"2") -> 0.61119978 | U36: =TDIST(F36,-1,0) -> #NUM! | V36: =TDIST(G36, 7,1) -> 0.0025949567 | W36: =TDIST(H36,H36,2) -> #NUM! | X36: =TDIST(I36,I36,1) -> 1.4243035e-55 | Y36: =TDIST(J36,I36,2) -> 0.3213265 | Z36: =TDIST(K36,I36,1) -> #VALUE! | AA36: =TDIST(L36,J36,1) -> #N/A | AB36: =TDIST(M36,K36,1) -> #DIV/0! | AC36: =TDIST(N36,L36,1) -> #NAME? | AD36: =TDIST(O36,M36,1) -> #NULL! | AE36: =TDIST(P36,N36,1) -> #NUM! | AF36: =TDIST(Q36,O36,1) -> #REF! | AG36: {=TDIST(C36:Q36,3,1)} -> 0.5 | AH36: {=TDIST(C36:Q36,3,2)} -> 1 | AI36: 0.015392438 | AJ36: 0.534327 | AK36: 0.057668886 | AL36: 0.028008456 | AM36: 1 | AN36: 1.0199594e-05 | AO36: 0.39100222 | AP36: #VALUE! | AQ36: #N/A | AR36: #DIV/0! | AS36: #NAME? | AT36: #NULL! | AU36: #NUM! | AV36: #REF! | AW36: #N/A
A37: TINV | B37: DONE | C37: 10 | D37: 0.1 | E37: 0.7 | F37: 100 | G37: 4 | I37: 13/01/1900 | J37: TRUE | K37: #VALUE! | L37: #N/A | M37: #DIV/0! | N37: #NAME? | O37: #NULL! | P37: #NUM! | Q37: #REF! | R37: =TINV(C37,0.4) -> #NUM! | S37: =TINV(D37,9) -> 1.8331129 | T37: =TINV(0.4,E37) -> #NUM! | U37: =TINV(0.01, F37) -> 2.6258905 | V37: =TINV(D37,G37) -> 2.1318468 | W37: =TINV(H37,3) -> #NUM! | X37: =TINV(0.9,I37) -> 0.12813905 | Y37: =TINV(0.3,J37) -> 1.9626105 | Z37: =TINV(K37,C37) -> #VALUE! | AA37: =TINV(L37,D37) -> #N/A | AB37: =TINV(M37,E37) -> #DIV/0! | AC37: =TINV(N37,F37) -> #NAME? | AD37: =TINV(O37,G37) -> #NULL! | AE37: =TINV(P37,H37) -> #NUM! | AF37: =TINV(Q37,I37) -> #REF! | AG37: {=TINV(0.6, C37:Q37)} -> 0.54152804 | AH37: {=TINV(0.5, C37:Q37)} -> 0.69981206 | AI37: #NUM! | AJ37: #NUM! | AK37: 0.67695104 | AL37: 0.74069708 | AM37: #NUM! | AN37: 0.6938293 | AO37: 1 | AP37: #VALUE! | AQ37: #N/A | AR37: #DIV/0! | AS37: #NAME? | AT37: #NULL! | AU37: #NUM! | AV37: #REF! | AW37: #N/A
A38: TTEST | B38: DONE | C38: 10 | D38: 3.2 | E38: 0.7 | F38: 2 | G38: 4 | I38: 13/01/1900 | J38: TRUE | K38: #VALUE! | L38: #N/A | M38: #DIV/0! | N38: #NAME? | O38: #NULL! | P38: #NUM! | Q38: #REF! | R38: {=TTEST(C37:D38,E35:E38,{1;2;1;2;1;2},{1;2;3;1;2;3})} -> 0.065797941 | S38: {=TTEST(D38:E38,E38:G38,{1;2;1;2;1;2},{1;2;3;1;2;3})} -> #N/A | T38: {=TTEST(E38:F38,G38:H38,{1;2;1;2;1;2},{1;2;3;1;2;3})} -> #DIV/0! | U38: {=TTEST(D38,F38,{1;2;1;2;1;2},{1;2;3;1;2;3})} -> #DIV/0! | V38: {=TTEST(G38:I38,H38:J38,{1;2;1;2;1;2},{1;2;3;1;2;3})} -> #DIV/0! | W38: {=TTEST(H38:I38,J38:K38,{1;2;1;2;1;2},{1;2;3;1;2;3})} -> #VALUE! | X38: {=TTEST(I38:J38,K38:L38,{1;2;1;2;1;2},{1;2;3;1;2;3})} -> #VALUE! | Y38: {=TTEST(J38:K38,L38:M38,{1;2;1;2;1;2},{1;2;3;1;2;3})} -> #N/A | Z38: {=TTEST(K38:L38,M38:N38,{1;2;1;2;1;2},{1;2;3;1;2;3})} -> #VALUE! | AA38: {=TTEST(L38:M38,N38:O38,{1;2;1;2;1;2},{1;2;3;1;2;3})} -> #N/A | AB38: {=TTEST(M38:N38,O38:P38,{1;2;1;2;1;2},{1;2;3;1;2;3})} -> #DIV/0! | AC38: {=TTEST(N38:O38,P38:Q38,{1;2;1;2;1;2},{1;2;3;1;2;3})} -> #NAME? | AD38: {=TTEST(O38:P38,Q38:R38,{1;2;1;2;1;2},{1;2;3;1;2;3})} -> #NUM! | ... AF38: {=TTEST(Q38:R38,S38:T38,{1;2;1;2;1;2},{1;2;3;1;2;3})} -> #REF! | AG38: {=TTEST(C37:D38, F37:G38,{1;2;1;2;1;2},{1;2;3;1;2;3})} -> 0.20698538 | AH38: {=TTEST(D38:E38, E38:F38,{1;2;1;2;1;2},{1;2;3;1;2;3})} -> 0.40263573 | AI38: 0.40263573 | AJ38: 0.40263573 | AK38: 0.40263573 | AL38: 0.40263573 | AM38: 0.40263573 | AN38: 0.40263573 | AO38: 0.40263573 | AP38: 0.40263573 | AQ38: 0.40263573 | AR38: 0.40263573 | AS38: 0.40263573 | AT38: 0.40263573 | AU38: 0.40263573 | AV38: 0.40263573 | AW38: 0.40263573
R39: 0.087928259 | S39: 0.86663407 | T39: #DIV/0! | U39: #DIV/0! | V39: #DIV/0! | W39: #VALUE! | X39: #VALUE! | Y39: #VALUE! | Z39: #VALUE! | AA39: #N/A | AB39: #DIV/0! | AC39: #NAME? | AD39: #NUM! | AE39: #NUM! | AF39: #REF! | AG39: 0.40674227 | AH39: 0.7116584 | AI39: 0.7116584 | AJ39: 0.7116584 | AK39: 0.7116584 | AL39: 0.7116584 | AM39: 0.7116584 | AN39: 0.7116584 | AO39: 0.7116584 | AP39: 0.7116584 | AQ39: 0.7116584 | AR39: 0.7116584 | AS39: 0.7116584 | AT39: 0.7116584 | AU39: 0.7116584 | AV39: 0.7116584 | AW39: 0.7116584
R40: 0.067244219 | S40: 0.43641889 | T40: #DIV/0! | U40: #DIV/0! | V40: #DIV/0! | W40: #VALUE! | X40: #VALUE! | Y40: #VALUE! | Z40: #VALUE! | AA40: #N/A | AB40: #DIV/0! | AC40: #NAME? | AD40: #NUM! | AE40: #NUM! | AF40: #REF! | AG40: 0.21843313 | AH40: 0.36159898 | AI40: 0.36159898 | AJ40: 0.36159898 | AK40: 0.36159898 | AL40: 0.36159898 | AM40: 0.36159898 | AN40: 0.36159898 | AO40: 0.36159898 | AP40: 0.36159898 | AQ40: 0.36159898 | AR40: 0.36159898 | AS40: 0.36159898 | AT40: 0.36159898 | AU40: 0.36159898 | AV40: 0.36159898 | AW40: 0.36159898
...

Sheet CUBE
A1: COVERAGE | B1: =COUNTIF(B3:B59,"=DONE")/COUNTA(A3:A59) -> 0 | C1: INPUTS | R1: EVAL
A2: FUNCTION | B2: STATUS | C2: NUMERIC | H2: EMPTY | I2: STRING | J2: BOOL | K2: ERROR | R2: NUMERIC | W2: EMPTY | X2: STRING | Y2: BOOL | Z2: ERROR | AG2: ARRAY -> VALUE | AH2: ARRAY -> ARRAY
A3: CUBEKPIMEMBER
A4: CUBEMEMBER
A5: CUBEMEMBERPROPERTY
A6: CUBERANKEDMEMBER
A7: CUBESET
A8: CUBESETCOUNT
A9: CUBEVALUE

Sheet DATABASE
A1: COVERAGE | B1: =COUNTIF(B3:B59,"=DONE")/COUNTA(A3:A59) -> 0 | C1: INPUTS | R1: EVAL
A2: FUNCTION | B2: STATUS | C2: NUMERIC | H2: EMPTY | I2: STRING | J2: BOOL | K2: ERROR | R2: NUMERIC | W2: EMPTY | X2: STRING | Y2: BOOL | Z2: ERROR | AG2: ARRAY -> VALUE | AH2: ARRAY -> ARRAY
A3: DAVERAGE
A4: DCOUNT
A5: DCOUNTA
A6: DGET
A7: DMAX
A8: DMIN
A9: DPRODUCT
A10: DSTDEV
A11: DSTDEVP
A12: DSUM
A13: DVAR
A14: DVARP

Sheet DATE & TIME
A1: COVERAGE | B1: =COUNTIF(B3:B275,"=DONE")/COUNTA(A3:A275) -> 1 | C1: INPUTS | R1: EVAL
A2: FUNCTION | B2: STATUS | C2: NUMERIC | H2: EMPTY | I2: STRING | J2: BOOL | K2: ERROR | R2: NUMERIC | W2: EMPTY | X2: STRING | Y2: BOOL | Z2: ERROR | AG2: ARRAY -> VALUE | AH2: ARRAY -> ARRAY
A3: DATE | B3: DONE | C3: 1987 | D3: 8 | E3: 1 | F3: 0.7 | G3: 0 | I3: -1 | J3: TRUE | K3: #VALUE! | L3: #N/A | M3: #DIV/0! | N3: #NAME? | O3: #NULL! | P3: #NUM! | Q3: #REF! | R3: =DATE(C3,D3,E3) -> 31990 | S3: =DATE(C3,D3,F3) -> 31989 | T3: =DATE(0.9,0.9,0.9) -> #NUM! | U3: =DATE(0,1,0) -> 0 | V3: =DATE(1,0,0) -> 335 | W3: =DATE(C3,D3,H3) -> 31989 | X3: =DATE(D3,E3,I3) -> 2921 | Y3: =DATE(E3,F3,J3) -> 336 | Z3: =DATE(F3,G3,K3) -> #VALUE! | AA3: =DATE(G3,H3,L3) -> #N/A | AB3: =DATE(H3,I3,M3) -> #DIV/0! | AC3: =DATE(I3,J3,N3) -> #NAME? | AD3: =DATE(J3,O3,K3) -> #NULL! | AE3: =DATE(C3,P3,L3) -> #NUM! | AF3: =DATE(Q3,K3,M3) -> #REF! | AG3: {=DATE(C3,D3,E3:H3)} -> 31990 | AH3: {=DATE(C3,D3,E3:G3)} -> 31990 | AI3: 31989 | AJ3: 31989 | AK3: #N/A | AL3: {=DATE(C3:E3,H3,D3:F3)} -> 31754 | AM3: 2892 | AN3: 335 | AO3: {=DATE(C3:I3,H3,K3:Q3)} -> #VALUE! | AP3: #N/A | AQ3: #DIV/0! | AR3: #NAME? | AS3: #NULL! | AT3: #NUM! | AU3: #REF! | AV3: #N/A | AW3: #N/A
A4: DATEDIF | B4: DONE | C4: 1987 | D4: 8 | E4: 1 | F4: 0.7 | G4: 0 | I4: -1 | J4: TRUE | K4: #VALUE! | L4: #N/A | M4: #DIV/0! | N4: #NAME? | O4: #NULL! | P4: #NUM! | Q4: #REF! | R4: =DATEDIF(D4, C4,"YD") -> 153 | S4: =DATEDIF(E4, D4,"Y") -> 0 | T4: =DATEDIF(F4, E4,"D") -> 1 | U4: =DATEDIF(G4, F4,"M") -> 0 | V4: =DATEDIF(H4, G4,"YM") -> 0 | W4: =DATEDIF(I4, H4,"YD") -> #NUM! | X4: =DATEDIF(J4, I4,"YD") -> #NUM! | Y4: =DATEDIF(K4, J4,"YD") -> #VALUE! | Z4: =DATEDIF(G4, F4,L4) -> #N/A | AA4: =DATEDIF(M4, L4,"YD") -> #DIV/0! | AB4: =DATEDIF(H4, G4,"a") -> #NUM! | AC4: =DATEDIF(O4, N4,"YD") -> #NULL! | AD4: =DATEDIF(P4, O4,"YD") -> #NUM! | AE4: =DATEDIF(Q4, P4,"YD") -> #REF! | AF4: =DATEDIF(R4, Q4,"YD") -> #REF! | AG4: {=DATEDIF(E4:F4,C4:D4, "D")} -> 1986 | AH4: {=DATEDIF(E4:K4,C4:I4, "D")} -> 1986 | AI4: 8 | AJ4: 1 | AK4: 0 | AL4: #NUM! | AM4: #NUM! | AN4: #VALUE! | AO4: #N/A | AP4: #N/A | AQ4: #N/A | AR4: #N/A | AS4: #N/A | AT4: #N/A | AU4: #N/A | AV4: #N/A | AW4: #N/A
A5: DATEVALUE | B5: DONE | C5: 1987 | D5: 8 | E5: 1 | F5: 0.7 | G5: 0 | I5: 1/1/1987 02:00 AM | J5: TRUE | K5: #VALUE! | L5: #N/A | M5: #DIV/0! | N5: #NAME? | O5: #NULL! | P5: #NUM! | Q5: #REF! | R5: =DATEVALUE(C5) -> #VALUE! | S5: =DATEVALUE(D5) -> #VALUE! | T5: =DATEVALUE(E5) -> #VALUE! | U5: =DATEVALUE(F5) -> #VALUE! | V5: =DATEVALUE(G5) -> #VALUE! | W5: =DATEVALUE(H5) -> #VALUE! | X5: =DATEVALUE(I5) -> 31778 | Y5: =DATEVALUE(J5) -> #VALUE! | ... AF5: =DATEVALUE(Q5) -> #REF! | AG5: {=DATEVALUE(I5:J5)} -> 31778 | AH5: {=DATEVALUE(C5:Q5)} -> #VALUE! | AI5: #VALUE! | AJ5: #VALUE! | AK5: #VALUE! | AL5: #VALUE! | AM5: #VALUE! | AN5: 31778 | AO5: #VALUE! | AP5: #VALUE! | AQ5: #N/A | AR5: #DIV/0! | AS5: #NAME? | AT5: #NULL! | AU5: #NUM! | AV5: #REF! | AW5: #N/A
A6: DAY | B6: DONE | C6: 1987 | D6: -1 | E6: 2958466 | F6: 0.7 | G6: 0 | I6: 600 | J6: TRUE | K6: #VALUE! | L6: #N/A | M6: #DIV/0! | N6: #NAME? | O6: #NULL! | P6: #NUM! | Q6: #REF! | R6: =DAY(C6) -> 9 | S6: =DAY(D6) -> #NUM! | T6: =DAY(E6) -> #NUM! | U6: =DAY(F6) -> 0 | V6: =DAY(G6) -> 0 | W6: =DAY(H6) -> 0 | X6: =DAY(I6) -> 22 | Y6: =DAY(J6) -> 1 | ... AF6: =DAY(Q6) -> #REF! | AG6: {=DAY(I6:J6)} -> 22 | AH6: {=DAY(C6:Q6)} -> 9 | AI6: #NUM! | AJ6: #NUM! | AK6: 0 | AL6: 0 | AM6: 0 | AN6: 22 | AO6: 1 | AP6: #VALUE! | AQ6: #N/A | AR6: #DIV/0! | AS6: #NAME? | AT6: #NULL! | AU6: #NUM! | AV6: #REF! | AW6: #N/A
A7: DAYS | B7: DONE | C7: 1987 | D7: -1 | E7: 2958466 | F7: 0.7 | G7: 0 | I7: 600 | J7: TRUE | K7: #VALUE! | L7: #N/A | M7: #DIV/0! | N7: #NAME? | O7: #NULL! | P7: #NUM! | Q7: #REF! | R7: =_xlfn.DAYS(C7,D7) -> #NUM! | S7: =_xlfn.DAYS(D7,E7) -> #NUM! | T7: =_xlfn.DAYS(E7,F7) -> #NUM! | U7: =_xlfn.DAYS(F7,G7) -> 0 | V7: =_xlfn.DAYS(G7,H7) -> 0 | W7: =_xlfn.DAYS(H7,I7) -> -600 | X7: =_xlfn.DAYS(I7,J7) -> 599 | Y7: =_xlfn.DAYS(J7,K7) -> #VALUE! | ... AF7: =_xlfn.DAYS(Q7,R7) -> #REF! | AG7: {=_xlfn.DAYS(E7:F7,I7)} -> #NUM! | AH7: {=_xlfn.DAYS(C7:Q7,C7)} -> 0 | AI7: #NUM! | AJ7: #NUM! | AK7: -1987 | AL7: -1987 | AM7: -1987 | AN7: -1387 | AO7: -1986 | AP7: #VALUE! | AQ7: #N/A | AR7: #DIV/0! | AS7: #NAME? | AT7: #NULL! | AU7: #NUM! | AV7: #REF! | AW7: #N/A
A8: DAYS360 | B8: DONE | C8: 1987 | D8: -1 | E8: 2958466 | F8: 0.7 | G8: 0 | I8: 600 | J8: TRUE | K8: #VALUE! | L8: #N/A | M8: #DIV/0! | N8: #NAME? | O8: #NULL! | P8: #NUM! | Q8: #REF! | R8: =DAYS360(C8,E8,1) -> #NUM! | S8: =DAYS360(D8,F8,1) -> #NUM! | T8: =DAYS360(E8,G8,1) -> #NUM! | U8: =DAYS360(F8,H8,1) -> 0 | V8: =DAYS360(G8,I8,1) -> 592 | W8: =DAYS360(H8,J8,1) -> 1 | X8: =DAYS360(I8,K8,1) -> #VALUE! | Y8: =DAYS360(J8,L8,1) -> #N/A | ... AF8: =DAYS360(Q8,S8,1) -> #REF! | AG8: {=DAYS360(E8:F8,I8)} -> #NUM! | AH8: {=DAYS360(C7:Q7,C7)} -> 0 | AI8: #NUM! | AJ8: #NUM! | AK8: 1959 | AL8: 1959 | AM8: 1959 | AN8: 1367 | AO8: 1958 | AP8: #VALUE! | AQ8: #N/A | AR8: #DIV/0! | AS8: #NAME? | AT8: #NULL! | AU8: #NUM! | AV8: #REF! | AW8: #N/A
A9: EDATE | B9: DONE | C9: 1987 | D9: 8 | E9: 1 | F9: 0.7 | G9: 0 | I9: 1/1/1987 02:00 AM | J9: TRUE | K9: #VALUE! | L9: #N/A | M9: #DIV/0! | N9: #NAME? | O9: #NULL! | P9: #NUM! | Q9: #REF! | R9: =EDATE(C9,D9) -> 2232 | S9: =EDATE(D9,"2") -> 68 | T9: =EDATE(E9,".55") -> 1 | U9: =EDATE(J9,G9) -> #VALUE! | V9: =EDATE(G9,H9) -> 0 | W9: =EDATE(F9,I9) -> 967223 | X9: =EDATE(I9,H9) -> 31778 | Y9: =EDATE(I9,J9) -> #VALUE! | Z9: =EDATE(K9,L9) -> #VALUE! | AA9: =EDATE(L9,M9) -> #N/A | AB9: =EDATE(M9,N9) -> #DIV/0! | AC9: =EDATE(N9,O9) -> #NAME? | AD9: =EDATE(O9,P9) -> #NULL! | AE9: =EDATE(P9,Q9) -> #NUM! | AF9: =EDATE(Q9,R9) -> #REF! | AG9: {=EDATE(I9,C9:G9)} -> #VALUE! | AH9: {=EDATE(E9:I9,C9:G9)} -> #VALUE! | AI9: #VALUE! | AJ9: #VALUE! | AK9: #VALUE! | AL9: #VALUE! | AM9: #VALUE! | AN9: #VALUE! | AO9: #VALUE! | AP9: #VALUE! | AQ9: #VALUE! | AR9: #VALUE! | AS9: #VALUE! | AT9: #VALUE! | AU9: #VALUE! | AV9: #VALUE! | AW9: #VALUE!
A10: EOMONTH | B10: DONE | C10: 1987 | D10: 8 | E10: 1 | F10: 0.7 | G10: 0 | I10: 1/1/1987 02:00 AM | J10: TRUE | K10: #VALUE! | L10: #N/A | M10: #DIV/0! | N10: #NAME? | O10: #NULL! | P10: #NUM! | Q10: #REF! | R10: =EOMONTH(C10,D10) -> 2251 | S10: =EOMONTH(D10,"2") -> 91 | T10: =EOMONTH(E10,".55") -> 31 | U10: =EOMONTH(J10,G10) -> #VALUE! | V10: =EOMONTH(G10,H10) -> 31 | W10: =EOMONTH(F10,I10) -> 967254 | X10: =EOMONTH(I10,H10) -> 31808 | Y10: =EOMONTH(I10,J10) -> #VALUE! | Z10: =EOMONTH(K10,L10) -> #VALUE! | AA10: =EOMONTH(L10,M10) -> #N/A | AB10: =EOMONTH(M10,N10) -> #DIV/0! | AC10: =EOMONTH(N10,O10) -> #NAME? | AD10: =EOMONTH(O10,P10) -> #NULL! | AE10: =EOMONTH(P10,Q10) -> #NUM! | AF10: =EOMONTH(Q10,R10) -> #REF! | AG10: {=EOMONTH(I10,C10:G10)} -> #VALUE! | AH10: {=EOMONTH(E10:I10,C10:G10)} -> #VALUE! | AI10: #VALUE! | AJ10: #VALUE! | AK10: #VALUE! | AL10: #VALUE! | AM10: #VALUE! | AN10: #VALUE! | AO10: #VALUE! | AP10: #VALUE! | AQ10: #VALUE! | AR10: #VALUE! | AS10: #VALUE! | AT10: #VALUE! | AU10: #VALUE! | AV10: #VALUE! | AW10: #VALUE!
A11: HOUR | B11: DONE | C11: 0.44 | D11: -1 | E11: 0.33 | F11: 1.4 | G11: 0 | I11: 3 | J11: TRUE | K11: #VALUE! | L11: #N/A | M11: #DIV/0! | N11: #NAME? | O11: #NULL! | P11: #NUM! | Q11: #REF! | R11: =HOUR(C11) -> 10 | S11: =HOUR(D11) -> #NUM! | T11: =HOUR(E11) -> 7 | U11: =HOUR(F11) -> 9 | V11: =HOUR(G11) -> 0 | W11: =HOUR(H11) -> 0 | X11: =HOUR(I11) -> 0 | Y11: =HOUR(J11) -> 0 | ... AF11: =HOUR(Q11) -> #REF! | AG11: {=HOUR(I6:J6)} -> 0 | AH11: {=HOUR(C11:Q11)} -> 10 | AI11: #NUM! | AJ11: 7 | AK11: 9 | AL11: 0 | AM11: 0 | AN11: 0 | AO11: 0 | AP11: #VALUE! | AQ11: #N/A | AR11: #DIV/0! | AS11: #NAME? | AT11: #NULL! | AU11: #NUM! | AV11: #REF! | AW11: #N/A
A12: ISOWEEKNUM | B12: DONE | C12: 1987 | D12: 8 | E12: 1 | F12: 0.7 | G12: 0 | I12: 1/1/1987 05:00 AM | J12: TRUE | K12: #VALUE! | L12: #N/A | M12: #DIV/0! | N12: #NAME? | O12: #NULL! | P12: #NUM! | Q12: #REF! | R12: =_xlfn.ISOWEEKNUM(C12) -> 23 | S12: =_xlfn.ISOWEEKNUM(D12) -> 1 | T12: =_xlfn.ISOWEEKNUM(E12) -> 52 | U12: =_xlfn.ISOWEEKNUM(F12) -> 52 | V12: =_xlfn.ISOWEEKNUM(G12) -> 52 | W12: =_xlfn.ISOWEEKNUM(H12) -> 52 | X12: =_xlfn.ISOWEEKNUM(I12) -> 1 | Y12: =_xlfn.ISOWEEKNUM(J12) -> 52 | ... AF12: =_xlfn.ISOWEEKNUM(Q12) -> #REF! | AG12: {=_xlfn.ISOWEEKNUM(C12:Q12)} -> 23 | AH12: {=_xlfn.ISOWEEKNUM(C12:Q12)} -> 23 | AI12: 1 | AJ12: 52 | AK12: 52 | AL12: 52 | AM12: 52 | AN12: 1 | AO12: 52 | AP12: #VALUE! | AQ12: #N/A | AR12: #DIV/0! | AS12: #NAME? | AT12: #NULL! | AU12: #NUM! | AV12: #REF! | AW12: #N/A
A13: MINUTE | B13: DONE | C13: 0.44 | D13: -1 | E13: 0.33 | F13: 1.4 | G13: 0 | I13: 3 | J13: TRUE | K13: #VALUE! | L13: #N/A | M13: #DIV/0! | N13: #NAME? | O13: #NULL! | P13: #NUM! | Q13: #REF! | R13: =MINUTE(C13) -> 33 | S13: =MINUTE(D13) -> #NUM! | T13: =MINUTE(E13) -> 55 | U13: =MINUTE(F13) -> 36 | V13: =MINUTE(G13) -> 0 | W13: =MINUTE(H13) -> 0 | X13: =MINUTE(I13) -> 0 | Y13: =MINUTE(J13) -> 0 | ... AF13: =MINUTE(Q13) -> #REF! | AG13: {=MINUTE(I8:J8)} -> 0 | AH13: {=MINUTE(C13:Q13)} -> 33 | AI13: #NUM! | AJ13: 55 | AK13: 36 | AL13: 0 | AM13: 0 | AN13: 0 | AO13: 0 | AP13: #VALUE! | AQ13: #N/A | AR13: #DIV/0! | AS13: #NAME? | AT13: #NULL! | AU13: #NUM! | AV13: #REF! | AW13: #N/A
A14: MONTH | B14: DONE | C14: 1987 | D14: 8 | E14: 1 | F14: 0.7 | G14: 0 | I14: 600 | J14: TRUE | K14: #VALUE! | L14: #N/A | M14: #DIV/0! | N14: #NAME? | O14: #NULL! | P14: #NUM! | Q14: #REF! | R14: =MONTH(C14) -> 6 | S14: =MONTH(D14) -> 1 | T14: =MONTH(E14) -> 1 | U14: =MONTH(F14) -> 1 | V14: =MONTH(G14) -> 1 | W14: =MONTH(H14) -> 1 | X14: =MONTH(I14) -> 8 | Y14: =MONTH(J14) -> 1 | ... AF14: =MONTH(Q14) -> #REF! | AG14: {=MONTH(I6:J6)} -> 8 | AH14: {=MONTH(C14:Q14)} -> 6 | AI14: 1 | AJ14: 1 | AK14: 1 | AL14: 1 | AM14: 1 | AN14: 8 | AO14: 1 | AP14: #VALUE! | AQ14: #N/A | AR14: #DIV/0! | AS14: #NAME? | AT14: #NULL! | AU14: #NUM! | AV14: #REF! | AW14: #N/A
A15: NETWORKDAYS | B15: DONE | C15: 1987 | D15: 8 | E15: 1 | F15: 0.7 | G15: 0 | I15: 600 | J15: TRUE | K15: #VALUE! | L15: #N/A | M15: #DIV/0! | N15: #NAME? | O15: #NULL! | P15: #NUM! | Q15: #REF! | R15: =NETWORKDAYS("2020-1-1","2024-1-1",C15) -> 1044 | S15: =NETWORKDAYS("2020-1-1","2024-1-1",D15) -> 1044 | T15: =NETWORKDAYS("2020-1-1","2024-1-1",E15) -> 1044 | U15: =NETWORKDAYS("2020-1-1","2024-1-1",F15) -> 1044 | V15: =NETWORKDAYS("2020-1-1","2024-1-1",G15) -> 1044 | W15: =NETWORKDAYS("2020-1-1","2024-1-1",H15) -> 1044 | X15: =NETWORKDAYS("2020-1-1","2024-1-1",I15) -> 1044 | Y15: =NETWORKDAYS("2020-1-1","2024-1-1",J15) -> #VALUE! | ... AF15: =NETWORKDAYS("2020-1-1","2024-1-1",Q15) -> #REF! | AG15: {=NETWORKDAYS("2020-1-1",{"2024-7-1","2010-3-2","2010-2-1"})} -> 1174 | AH15: {=NETWORKDAYS("2020-1-1",{"2024-7-1","2010-3-2","2010-2-1"})} -> 1174 | AI15: -2567 | AJ15: -2588
A16: NETWORKDAYS.INTL | B16: DONE | C16: 1987 | D16: 8.8 | E16: 1 | F16: 11 | G16: 0 | I16: 600 | J16: TRUE | K16: #VALUE! | L16: #N/A | M16: #DIV/0! | N16: #NAME? | O16: #NULL! | P16: #NUM! | Q16: #REF! | R16: =NETWORKDAYS.INTL("2020-1-1","2024-1-1",C16) -> #NUM! | S16: =NETWORKDAYS.INTL("2020-1-1","2024-1-1",D16) -> #NUM! | T16: =NETWORKDAYS.INTL("2020-1-1","2024-1-1",E16) -> 1044 | U16: =NETWORKDAYS.INTL("2020-1-1","2024-1-1",F16) -> 1253 | V16: =NETWORKDAYS.INTL("2020-1-1","2024-1-1","1111101") -> 209 | W16: =NETWORKDAYS.INTL("2020-1-1","2024-1-1",H16) -> #NUM! | X16: =NETWORKDAYS.INTL("2020-1-1","2024-1-1",I16) -> #VALUE! | Y16: =NETWORKDAYS.INTL("2020-1-1","2024-1-1",J16) -> 1044 | Z16: =NETWORKDAYS.INTL("2020-1-1","2024-1-1",K16) -> #VALUE! | AA16: =NETWORKDAYS.INTL("2020-1-1","2024-1-1",L16) -> #VALUE! | AB16: =NETWORKDAYS.INTL("2020-1-1","2024-1-1",M16) -> #VALUE! | AC16: =NETWORKDAYS.INTL("2020-1-1","2024-1-1",N16) -> #VALUE! | AD16: =NETWORKDAYS.INTL("2020-1-1","2024-1-1",O16) -> #VALUE! | ... AF16: =NETWORKDAYS.INTL("2020-1-1","2024-1-1",Q16) -> #VALUE! | AG16: {=NETWORKDAYS.INTL("2020-1-1","2024-1-1",C16:I16)} -> #NUM! | AH16: {=NETWORKDAYS.INTL("2020-1-1","2024-1-1",C16:Q16)} -> #NUM! | AI16: #NUM! | AJ16: 1044 | AK16: 1253 | AL16: #NUM! | AM16: #NUM! | AN16: #VALUE! | AO16: 1044 | AP16: #VALUE! | AQ16: #VALUE! | AR16: #VALUE! | AS16: #VALUE! | AT16: #VALUE! | AU16: #VALUE! | AV16: #VALUE! | AW16: #N/A
A17: NOW | B17: DONE | W17: =IF(NOW(),1,0) -> 1
A18: SECOND | B18: DONE | C18: 0.44 | D18: -1 | E18: 0.33 | F18: 1.4 | G18: 0 | I18: 3 | J18: TRUE | K18: #VALUE! | L18: #N/A | M18: #DIV/0! | N18: #NAME? | O18: #NULL! | P18: #NUM! | Q18: #REF! | R18: =SECOND(C18) -> 36 | S18: =SECOND(D18) -> #NUM! | T18: =SECOND(E18) -> 12 | U18: =SECOND(F18) -> 0 | V18: =SECOND(G18) -> 0 | W18: =SECOND(H18) -> 0 | X18: =SECOND(I18) -> 0 | Y18: =SECOND(J18) -> 0 | ... AF18: =SECOND(Q18) -> #REF! | AG18: {=SECOND(I13:J13)} -> 0 | AH18: {=SECOND(C18:Q18)} -> 36 | AI18: #NUM! | AJ18: 12 | AK18: 0 | AL18: 0 | AM18: 0 | AN18: 0 | AO18: 0 | AP18: #VALUE! | AQ18: #N/A | AR18: #DIV/0! | AS18: #NAME? | AT18: #NULL! | AU18: #NUM! | AV18: #REF! | AW18: #N/A
A19: TIME | B19: DONE | C19: 32767.99 | D19: -1 | E19: 67 | F19: 0.7 | G19: 0 | I19: 60 | J19: TRUE | K19: #VALUE! | L19: #N/A | M19: #DIV/0! | N19: #NAME? | O19: #NULL! | P19: #NUM! | Q19: #REF! | R19: =TIME(C19,D19,E19) -> 0.29174769 | S19: =TIME(C19,D19,F19) -> 0.29097222 | T19: =TIME(0.9,0.9,0.9) -> 0 | U19: =TIME(0,1,0) -> 0.00069444444 | V19: =TIME(1,0,0) -> 0.041666667 | W19: =TIME(C19,D19,H19) -> 0.29097222 | X19: =TIME(D19,E19,I19) -> 0.0055555556 | Y19: =TIME(E19,F19,J19) -> 0.79167824 | Z19: =TIME(F19,G19,K19) -> #VALUE! | AA19: =TIME(G19,H19,L19) -> #N/A | AB19: =TIME(H19,I19,M19) -> #DIV/0! | AC19: =TIME(I19,J19,N19) -> #NAME? | AD19: =TIME(J19,O19,K19) -> #NULL! | AE19: =TIME(C19,P19,L19) -> #NUM! | AF19: =TIME(Q19,K19,M19) -> #REF! | AG19: {=TIME(C19,D19,E19:H19)} -> 0.29174769 | AH19: {=TIME(C19,D19,E19:G19)} -> 0.29174769 | AI19: 0.29097222 | AJ19: 0.29097222 | AK19: #N/A | AL19: {=TIME(C19:E19,H19,D19:F19)} -> 0.29165509 | AM19: #NUM! | AN19: 0.79166667 | AO19: {=TIME(C19:I19,H19,K19:Q19)} -> #VALUE! | AP19: #N/A | AQ19: #DIV/0! | AR19: #NAME? | AS19: #NULL! | AT19: #NUM! | AU19: #REF! | AV19: #N/A | AW19: #N/A
A20: TIMEVALUE | B20: DONE | C20: 1987 | D20: 8 | E20: 1 | F20: 0.7 | G20: 0 | I20: 1/1/1987 05:00 AM | J20: TRUE | K20: #VALUE! | L20: #N/A | M20: #DIV/0! | N20: #NAME? | O20: #NULL! | P20: #NUM! | Q20: #REF! | R20: =TIMEVALUE(C20) -> #VALUE! | S20: =TIMEVALUE(D20) -> #VALUE! | T20: =TIMEVALUE(E20) -> #VALUE! | U20: =TIMEVALUE(F20) -> #VALUE! | V20: =TIMEVALUE(G20) -> #VALUE! | W20: =TIMEVALUE(H20) -> #VALUE! | X20: =TIMEVALUE(I20) -> 0.20833333 | Y20: =TIMEVALUE(J20) -> #VALUE! | ... AF20: =TIMEVALUE(Q20) -> #REF! | AG20: {=TIMEVALUE(I20:J20)} -> 0.20833333 | AH20: {=TIMEVALUE(C20:Q20)} -> #VALUE! | AI20: #VALUE! | AJ20: #VALUE! | AK20: #VALUE! | AL20: #VALUE! | AM20: #VALUE! | AN20: 0.20833333 | AO20: #VALUE! | AP20: #VALUE! | AQ20: #N/A | AR20: #DIV/0! | AS20: #NAME? | AT20: #NULL! | AU20: #NUM! | AV20: #REF! | AW20: #N/A
A21: TODAY | B21: DONE | W21: =IF(TODAY(),1,0) -> 1
